Workbook
Name ATUAL_CARGA_TOTAL: RAMAL!$AB$12
Name ATUAL_CORRENTE_MAXIMA: RAMAL!$AB$6
Name ATUAL_DEMANDA_MAXIMA: RAMAL!$AB$8
Name ATUAL_DMDI_MEDIO: RAMAL!$AB$18
Name ATUAL_ENTRADAS_RAMAIS: RAMAL!$A$18:$U$77
Name ATUAL_FATOR_LEITURA_TRAFO: RAMAL!$AB$14
Name AUX_CLAN: DB!$C$30:$F$330
Name CONDUTORES: CABOS[]
Name COORD: COORDENADAS!$C$2:$E$63
Name DEM_ATUAL: DB!$K$7
Name DMDI: RAMAL!$AA$30
Name fator_potencia: DB!$K$2
Name QT_MT: DB!$K$4
Name QT_MTTR: DB!$K$10
Name QT_MTTR2: DB!$K$19
Name QT_MTTR3: DB!$K$26
Name QT_TR: DB!$K$8
Name RAMA_PROJ1: #REF!
Name RAMA_PROJ2: #REF!
Name RAMAIS_ATUAL: RAMAL!$A$18:$Y$77
Name RAMAIS_PROJ1: #REF!
Name T_LINHA_MONO: DB!$M$14
Name T_LINHA_TRF: DB!$M$13
Name TAB_CLAN_DMDI: DB!$A$30:$B$411
Name TR_ATUAL: DB!$K$6
Name CONDUTORES: CABOS[]
Name CONDUTORES: CABOS[]
Name CONDUTORES: CABOS[]
Name CONDUTORES: CABOS[]
Name CONDUTORES: CABOS[]
Name CONDUTORES: CABOS[]
Name CONDUTORES: CABOS[]

Sheet DB
A1: CONDUTORES | B1: (A) | C1: Resistência | D1: Reatância | E1: α | F1: DIVISOR_R | G1: TEMP_LIM | H1: DELTA_TEMP_30 | I1: K_TERM_30 | P1: I_MIN | Q1: IN_PADRAO | S1: PARAMETRO | T1: VALOR | U1: UNIDADE | W1: CONDUTOR | X1: MATERIAL | Y1: COD_CONDUTOR
A2: 25 Al - Arm | C2: 1.5693 | D2: 0.1039 | E2: 0.00403 | F2: 1.2821 | G2: =IF(OR(A2="13 Al - DX",A2="13 Al - TX",A2="13 Al - QX",A2="21 Al - QX",A2="53 Al - QX"),70,90) | H2: =G2-30 | I2: =IFERROR(B2/H2,0) | J2: fator | K2: 0.92 | P2: =0 | Q2: =0 | S2: fator_potencia | T2: =K2 | U2: pu | W2: =INDEX(CABOS[CONDUTORES],1) | X2: =IF(ISNUMBER(FIND(" Cu",W2)),"CU",IF(ISNUMBER(FIND(" Al",W2)),"AL",IF(ISNUMBER(FIND(" AA",W2)),"AA","OUTRO"))) | Y2: =UPPER(SUBSTITUTE(SUBSTITUTE(SUBSTITUTE(SUBSTITUTE(W2," - ","_")," ","_"),"-","_"),".",""))
A3: 50 Al - Arm | C3: 0.8388 | D3: 0.1039 | E3: 0.00403 | F3: 1.2821 | G3: =IF(OR(A3="13 Al - DX",A3="13 Al - TX",A3="13 Al - QX",A3="21 Al - QX",A3="53 Al - QX"),70,90) | H3: =G3-30 | I3: =IFERROR(B3/H3,0) | M3: TRAFO | N3: Z% | P3: =6 | Q3: =6 | S3: QT_MT | T3: =K4 | U3: pu | W3: =INDEX(CABOS[CONDUTORES],2) | X3: =IF(ISNUMBER(FIND(" Cu",W3)),"CU",IF(ISNUMBER(FIND(" Al",W3)),"AL",IF(ISNUMBER(FIND(" AA",W3)),"AA","OUTRO"))) | Y3: =UPPER(SUBSTITUTE(SUBSTITUTE(SUBSTITUTE(SUBSTITUTE(W3," - ","_")," ","_"),"-","_"),".",""))
A4: 95 Al - Arm | B4: 237 | C4: 0.4197 | D4: 0.098 | E4: 0.00403 | F4: 1.2821 | G4: =IF(OR(A4="13 Al - DX",A4="13 Al - TX",A4="13 Al - QX",A4="21 Al - QX",A4="53 Al - QX"),70,90) | H4: =G4-30 | I4: =IFERROR(B4/H4,0) | J4: QT_MT | K4: 0.0183 | M4: 30 | N4: 0.035 | P4: =10 | Q4: =10 | S4: TR_ATUAL | T4: =K6 | U4: kVA | W4: =INDEX(CABOS[CONDUTORES],3) | X4: =IF(ISNUMBER(FIND(" Cu",W4)),"CU",IF(ISNUMBER(FIND(" Al",W4)),"AL",IF(ISNUMBER(FIND(" AA",W4)),"AA","OUTRO"))) | Y4: =UPPER(SUBSTITUTE(SUBSTITUTE(SUBSTITUTE(SUBSTITUTE(W4," - ","_")," ","_"),"-","_"),".",""))
A5: 150 Al - Arm | C5: 0.266 | D5: 0.096 | E5: 0.00403 | F5: 1.2821 | G5: =IF(OR(A5="13 Al - DX",A5="13 Al - TX",A5="13 Al - QX",A5="21 Al - QX",A5="53 Al - QX"),70,90) | H5: =G5-30 | I5: =IFERROR(B5/H5,0) | M5: 45 | N5: 0.035 | P5: =16 | Q5: =16 | S5: DEM_ATUAL | T5: =K7 | U5: kVA | W5: =INDEX(CABOS[CONDUTORES],4) | X5: =IF(ISNUMBER(FIND(" Cu",W5)),"CU",IF(ISNUMBER(FIND(" Al",W5)),"AL",IF(ISNUMBER(FIND(" AA",W5)),"AA","OUTRO"))) | Y5: =UPPER(SUBSTITUTE(SUBSTITUTE(SUBSTITUTE(SUBSTITUTE(W5," - ","_")," ","_"),"-","_"),".",""))
A6: 240 Al - Arm | B6: 395 | C6: 0.1665 | D6: 0.0858 | E6: 0.00403 | F6: 1.2821 | G6: =IF(OR(A6="13 Al - DX",A6="13 Al - TX",A6="13 Al - QX",A6="21 Al - QX",A6="53 Al - QX"),70,90) | H6: =G6-30 | I6: =IFERROR(B6/H6,0) | J6: TR_ATUAL | K6: =GERAL!O3 | M6: 75 | N6: 0.035 | P6: =20 | Q6: =20 | S6: QT_TR | T6: =K8 | U6: pu | W6: =INDEX(CABOS[CONDUTORES],5) | X6: =IF(ISNUMBER(FIND(" Cu",W6)),"CU",IF(ISNUMBER(FIND(" Al",W6)),"AL",IF(ISNUMBER(FIND(" AA",W6)),"AA","OUTRO"))) | Y6: =UPPER(SUBSTITUTE(SUBSTITUTE(SUBSTITUTE(SUBSTITUTE(W6," - ","_")," ","_"),"-","_"),".",""))
A7: 25 Al | C7: 1.5693 | D7: 0.109 | E7: 0.00403 | F7: 1.2821 | G7: =IF(OR(A7="13 Al - DX",A7="13 Al - TX",A7="13 Al - QX",A7="21 Al - QX",A7="53 Al - QX"),70,90) | H7: =G7-30 | I7: =IFERROR(B7/H7,0) | J7: DEM_ATUAL | K7: =GERAL!I9 | M7: 112.5 | N7: 0.035 | P7: =25 | Q7: =25 | S7: QT_MTTR | T7: =K10 | U7: pu | W7: =INDEX(CABOS[CONDUTORES],6) | X7: =IF(ISNUMBER(FIND(" Cu",W7)),"CU",IF(ISNUMBER(FIND(" Al",W7)),"AL",IF(ISNUMBER(FIND(" AA",W7)),"AA","OUTRO"))) | Y7: =UPPER(SUBSTITUTE(SUBSTITUTE(SUBSTITUTE(SUBSTITUTE(W7," - ","_")," ","_"),"-","_"),".",""))
A8: 35 Cu | C8: 0.6887 | D8: 0.1048 | E8: 0.00393 | F8: 1.2821 | G8: =IF(OR(A8="13 Al - DX",A8="13 Al - TX",A8="13 Al - QX",A8="21 Al - QX",A8="53 Al - QX"),70,90) | H8: =G8-30 | I8: =IFERROR(B8/H8,0) | J8: QT_TR | K8: =(DEM_ATUAL/TR_ATUAL)*VLOOKUP(TR_ATUAL,TRAFOS_Z[],2,0) | M8: 150 | N8: 0.035 | P8: =32 | Q8: =32 | W8: =INDEX(CABOS[CONDUTORES],7) | X8: =IF(ISNUMBER(FIND(" Cu",W8)),"CU",IF(ISNUMBER(FIND(" Al",W8)),"AL",IF(ISNUMBER(FIND(" AA",W8)),"AA","OUTRO"))) | Y8: =UPPER(SUBSTITUTE(SUBSTITUTE(SUBSTITUTE(SUBSTITUTE(W8," - ","_")," ","_"),"-","_"),".",""))
A9: 70 Cu | C9: 0.3523 | D9: 0.1024 | E9: 0.00393 | F9: 1.2821 | G9: =IF(OR(A9="13 Al - DX",A9="13 Al - TX",A9="13 Al - QX",A9="21 Al - QX",A9="53 Al - QX"),70,90) | H9: =G9-30 | I9: =IFERROR(B9/H9,0) | M9: 225 | N9: 0.035 | P9: =40 | Q9: =40 | W9: =INDEX(CABOS[CONDUTORES],8) | X9: =IF(ISNUMBER(FIND(" Cu",W9)),"CU",IF(ISNUMBER(FIND(" Al",W9)),"AL",IF(ISNUMBER(FIND(" AA",W9)),"AA","OUTRO"))) | Y9: =UPPER(SUBSTITUTE(SUBSTITUTE(SUBSTITUTE(SUBSTITUTE(W9," - ","_")," ","_"),"-","_"),".",""))
A10: 95 Al | C10: 0.4195 | D10: 0.0958 | E10: 0.00403 | F10: 1.2821 | G10: =IF(OR(A10="13 Al - DX",A10="13 Al - TX",A10="13 Al - QX",A10="21 Al - QX",A10="53 Al - QX"),70,90) | H10: =G10-30 | I10: =IFERROR(B10/H10,0) | J10: QT_MTTR | K10: =QT_MT+QT_TR | M10: 300 | N10: 0.035 | P10: =50 | Q10: =50 | W10: =INDEX(CABOS[CONDUTORES],9) | X10: =IF(ISNUMBER(FIND(" Cu",W10)),"CU",IF(ISNUMBER(FIND(" Al",W10)),"AL",IF(ISNUMBER(FIND(" AA",W10)),"AA","OUTRO"))) | Y10: =UPPER(SUBSTITUTE(SUBSTITUTE(SUBSTITUTE(SUBSTITUTE(W10," - ","_")," ","_"),"-","_"),".",""))
A11: 120 Cu | C11: 0.2023 | D11: 0.0971 | E11: 0.00393 | F11: 1.2821 | G11: =IF(OR(A11="13 Al - DX",A11="13 Al - TX",A11="13 Al - QX",A11="21 Al - QX",A11="53 Al - QX"),70,90) | H11: =G11-30 | I11: =IFERROR(B11/H11,0) | P11: =63 | Q11: =63 | W11: =INDEX(CABOS[CONDUTORES],10) | X11: =IF(ISNUMBER(FIND(" Cu",W11)),"CU",IF(ISNUMBER(FIND(" Al",W11)),"AL",IF(ISNUMBER(FIND(" AA",W11)),"AA","OUTRO"))) | Y11: =UPPER(SUBSTITUTE(SUBSTITUTE(SUBSTITUTE(SUBSTITUTE(W11," - ","_")," ","_"),"-","_"),".",""))
A12: 240 Al | B12: 476 | C12: 0.1663 | D12: 0.0897 | E12: 0.00403 | F12: 1.2821 | G12: =IF(OR(A12="13 Al - DX",A12="13 Al - TX",A12="13 Al - QX",A12="21 Al - QX",A12="53 Al - QX"),70,90) | H12: =G12-30 | I12: =IFERROR(B12/H12,0) | P12: =80 | Q12: =80 | W12: =INDEX(CABOS[CONDUTORES],11) | X12: =IF(ISNUMBER(FIND(" Cu",W12)),"CU",IF(ISNUMBER(FIND(" Al",W12)),"AL",IF(ISNUMBER(FIND(" AA",W12)),"AA","OUTRO"))) | Y12: =UPPER(SUBSTITUTE(SUBSTITUTE(SUBSTITUTE(SUBSTITUTE(W12," - ","_")," ","_"),"-","_"),".",""))
A13: 240 Cu | B13: 430 | C13: 0.1035 | D13: 0.0897 | E13: 0.00393 | F13: 1.2821 | G13: =IF(OR(A13="13 Al - DX",A13="13 Al - TX",A13="13 Al - QX",A13="21 Al - QX",A13="53 Al - QX"),70,90) | H13: =G13-30 | I13: =IFERROR(B13/H13,0) | M13: 220 | P13: =100 | Q13: =100 | W13: =INDEX(CABOS[CONDUTORES],12) | X13: =IF(ISNUMBER(FIND(" Cu",W13)),"CU",IF(ISNUMBER(FIND(" Al",W13)),"AL",IF(ISNUMBER(FIND(" AA",W13)),"AA","OUTRO"))) | Y13: =UPPER(SUBSTITUTE(SUBSTITUTE(SUBSTITUTE(SUBSTITUTE(W13," - ","_")," ","_"),"-","_"),".",""))
A14: 500 Cu | C14: 0.0568 | D14: 0.0849 | E14: 0.00393 | F14: 1.2821 | G14: =IF(OR(A14="13 Al - DX",A14="13 Al - TX",A14="13 Al - QX",A14="21 Al - QX",A14="53 Al - QX"),70,90) | H14: =G14-30 | I14: =IFERROR(B14/H14,0) | M14: =T_LINHA_TRF/SQRT(3) | P14: =125 | Q14: =125 | W14: =INDEX(CABOS[CONDUTORES],13) | X14: =IF(ISNUMBER(FIND(" Cu",W14)),"CU",IF(ISNUMBER(FIND(" Al",W14)),"AL",IF(ISNUMBER(FIND(" AA",W14)),"AA","OUTRO"))) | Y14: =UPPER(SUBSTITUTE(SUBSTITUTE(SUBSTITUTE(SUBSTITUTE(W14," - ","_")," ","_"),"-","_"),".",""))
A15: 10 Cu_CONC_bi | B15: 63 | C15: 2.3801 | D15: 0.101 | E15: 0.00403 | F15: 1.2821 | G15: =IF(OR(A15="13 Al - DX",A15="13 Al - TX",A15="13 Al - QX",A15="21 Al - QX",A15="53 Al - QX"),70,90) | H15: =G15-30 | I15: =IFERROR(B15/H15,0) | J15: TR_PROJ1 | K15: ='GERAL PROJ'!O3 | P15: =160 | Q15: =160 | W15: =INDEX(CABOS[CONDUTORES],14) | X15: =IF(ISNUMBER(FIND(" Cu",W15)),"CU",IF(ISNUMBER(FIND(" Al",W15)),"AL",IF(ISNUMBER(FIND(" AA",W15)),"AA","OUTRO"))) | Y15: =UPPER(SUBSTITUTE(SUBSTITUTE(SUBSTITUTE(SUBSTITUTE(W15," - ","_")," ","_"),"-","_"),".",""))
A16: 10 Cu_CONC_Tri | B16: 63 | C16: 2.3801 | D16: 0.101 | E16: 0.00403 | F16: 1.2821 | G16: =IF(OR(A16="13 Al - DX",A16="13 Al - TX",A16="13 Al - QX",A16="21 Al - QX",A16="53 Al - QX"),70,90) | H16: =G16-30 | I16: =IFERROR(B16/H16,0) | J16: DEM_PROJ1 | K16: =RAMAL!AC24 | P16: =200 | Q16: =200 | W16: =INDEX(CABOS[CONDUTORES],15) | X16: =IF(ISNUMBER(FIND(" Cu",W16)),"CU",IF(ISNUMBER(FIND(" Al",W16)),"AL",IF(ISNUMBER(FIND(" AA",W16)),"AA","OUTRO"))) | Y16: =UPPER(SUBSTITUTE(SUBSTITUTE(SUBSTITUTE(SUBSTITUTE(W16," - ","_")," ","_"),"-","_"),".",""))
A17: 16 Al_CONC_bi | B17: 63 | C17: 2.4978 | D17: 0.085 | E17: 0.00403 | F17: 1.2821 | G17: =IF(OR(A17="13 Al - DX",A17="13 Al - TX",A17="13 Al - QX",A17="21 Al - QX",A17="53 Al - QX"),70,90) | H17: =G17-30 | I17: =IFERROR(B17/H17,0) | J17: QT_TR | K17: =(K16/K15)*VLOOKUP(K15,TRAFOS_Z[],2,0) | P17: =250 | Q17: =250 | W17: =INDEX(CABOS[CONDUTORES],16) | X17: =IF(ISNUMBER(FIND(" Cu",W17)),"CU",IF(ISNUMBER(FIND(" Al",W17)),"AL",IF(ISNUMBER(FIND(" AA",W17)),"AA","OUTRO"))) | Y17: =UPPER(SUBSTITUTE(SUBSTITUTE(SUBSTITUTE(SUBSTITUTE(W17," - ","_")," ","_"),"-","_"),".",""))
A18: 16 Al_CONC_Tri | B18: 63 | C18: 2.4978 | D18: 0.85 | E18: 0.00403 | F18: 1.2821 | G18: =IF(OR(A18="13 Al - DX",A18="13 Al - TX",A18="13 Al - QX",A18="21 Al - QX",A18="53 Al - QX"),70,90) | H18: =G18-30 | I18: =IFERROR(B18/H18,0) | P18: =315 | Q18: =315 | W18: =INDEX(CABOS[CONDUTORES],17) | X18: =IF(ISNUMBER(FIND(" Cu",W18)),"CU",IF(ISNUMBER(FIND(" Al",W18)),"AL",IF(ISNUMBER(FIND(" AA",W18)),"AA","OUTRO"))) | Y18: =UPPER(SUBSTITUTE(SUBSTITUTE(SUBSTITUTE(SUBSTITUTE(W18," - ","_")," ","_"),"-","_"),".",""))
A19: 13 Al - DX | B19: 63 | C19: 2.6655 | D19: 0.1022 | E19: 0.00403 | F19: 1.2821 | G19: =IF(OR(A19="13 Al - DX",A19="13 Al - TX",A19="13 Al - QX",A19="21 Al - QX",A19="53 Al - QX"),70,90) | H19: =G19-30 | I19: =IFERROR(B19/H19,0) | J19: QT_MTTR2 | K19: =QT_MT+K17 | P19: =400 | Q19: =400 | W19: =INDEX(CABOS[CONDUTORES],18) | X19: =IF(ISNUMBER(FIND(" Cu",W19)),"CU",IF(ISNUMBER(FIND(" Al",W19)),"AL",IF(ISNUMBER(FIND(" AA",W19)),"AA","OUTRO"))) | Y19: =UPPER(SUBSTITUTE(SUBSTITUTE(SUBSTITUTE(SUBSTITUTE(W19," - ","_")," ","_"),"-","_"),".",""))
A20: 13 Al - TX | B20: 63 | C20: 2.6655 | D20: 0.1158 | E20: 0.00403 | F20: 1.2821 | G20: =IF(OR(A20="13 Al - DX",A20="13 Al - TX",A20="13 Al - QX",A20="21 Al - QX",A20="53 Al - QX"),70,90) | H20: =G20-30 | I20: =IFERROR(B20/H20,0) | P20: =500 | Q20: =500 | W20: =INDEX(CABOS[CONDUTORES],19) | X20: =IF(ISNUMBER(FIND(" Cu",W20)),"CU",IF(ISNUMBER(FIND(" Al",W20)),"AL",IF(ISNUMBER(FIND(" AA",W20)),"AA","OUTRO"))) | Y20: =UPPER(SUBSTITUTE(SUBSTITUTE(SUBSTITUTE(SUBSTITUTE(W20," - ","_")," ","_"),"-","_"),".",""))
A21: 13 Al - QX | B21: 63 | C21: 2.6655 | D21: 0.1384 | E21: 0.00403 | F21: 1.2821 | G21: =IF(OR(A21="13 Al - DX",A21="13 Al - TX",A21="13 Al - QX",A21="21 Al - QX",A21="53 Al - QX"),70,90) | H21: =G21-30 | I21: =IFERROR(B21/H21,0) | P21: =630 | Q21: =630 | W21: =INDEX(CABOS[CONDUTORES],20) | X21: =IF(ISNUMBER(FIND(" Cu",W21)),"CU",IF(ISNUMBER(FIND(" Al",W21)),"AL",IF(ISNUMBER(FIND(" AA",W21)),"AA","OUTRO"))) | Y21: =UPPER(SUBSTITUTE(SUBSTITUTE(SUBSTITUTE(SUBSTITUTE(W21," - ","_")," ","_"),"-","_"),".",""))
A22: 21 Al - QX | B22: 63 | C22: 1.677 | D22: 0.135 | E22: 0.00403 | F22: 1.2821 | G22: =IF(OR(A22="13 Al - DX",A22="13 Al - TX",A22="13 Al - QX",A22="21 Al - QX",A22="53 Al - QX"),70,90) | H22: =G22-30 | I22: =IFERROR(B22/H22,0) | J22: TR_PROJ2 | K22: ='GERAL PROJ2'!O3 | W22: =INDEX(CABOS[CONDUTORES],21) | X22: =IF(ISNUMBER(FIND(" Cu",W22)),"CU",IF(ISNUMBER(FIND(" Al",W22)),"AL",IF(ISNUMBER(FIND(" AA",W22)),"AA","OUTRO"))) | Y22: =UPPER(SUBSTITUTE(SUBSTITUTE(SUBSTITUTE(SUBSTITUTE(W22," - ","_")," ","_"),"-","_"),".",""))
A23: 53 Al - QX | B23: 63 | C23: 0.6641 | D23: 0.1311 | E23: 0.00403 | F23: 1.2821 | G23: =IF(OR(A23="13 Al - DX",A23="13 Al - TX",A23="13 Al - QX",A23="21 Al - QX",A23="53 Al - QX"),70,90) | H23: =G23-30 | I23: =IFERROR(B23/H23,0) | J23: DEM_PROJ2 | K23: =RAMAL!AE24 | W23: =INDEX(CABOS[CONDUTORES],22) | X23: =IF(ISNUMBER(FIND(" Cu",W23)),"CU",IF(ISNUMBER(FIND(" Al",W23)),"AL",IF(ISNUMBER(FIND(" AA",W23)),"AA","OUTRO"))) | Y23: =UPPER(SUBSTITUTE(SUBSTITUTE(SUBSTITUTE(SUBSTITUTE(W23," - ","_")," ","_"),"-","_"),".",""))
A24: 70 Al - MX | B24: 202 | C24: 0.5697 | D24: 0.126 | E24: 0.00403 | F24: 1.2821 | G24: =IF(OR(A24="13 Al - DX",A24="13 Al - TX",A24="13 Al - QX",A24="21 Al - QX",A24="53 Al - QX"),70,90) | H24: =G24-30 | I24: =IFERROR(B24/H24,0) | J24: QT_TR | K24: =(K23/K22)*VLOOKUP(K22,TRAFOS_Z[],2,0) | W24: =INDEX(CABOS[CONDUTORES],23) | X24: =IF(ISNUMBER(FIND(" Cu",W24)),"CU",IF(ISNUMBER(FIND(" Al",W24)),"AL",IF(ISNUMBER(FIND(" AA",W24)),"AA","OUTRO"))) | Y24: =UPPER(SUBSTITUTE(SUBSTITUTE(SUBSTITUTE(SUBSTITUTE(W24," - ","_")," ","_"),"-","_"),".",""))
A25: 185 Al - MX | B25: 355 | C25: 0.2404 | D25: 0.1178 | E25: 0.00403 | F25: 1.4368 | G25: =IF(OR(A25="13 Al - DX",A25="13 Al - TX",A25="13 Al - QX",A25="21 Al - QX",A25="53 Al - QX"),70,90) | H25: =G25-30 | I25: =IFERROR(B25/H25,0) | W25: =INDEX(CABOS[CONDUTORES],24) | X25: =IF(ISNUMBER(FIND(" Cu",W25)),"CU",IF(ISNUMBER(FIND(" Al",W25)),"AL",IF(ISNUMBER(FIND(" AA",W25)),"AA","OUTRO"))) | Y25: =UPPER(SUBSTITUTE(SUBSTITUTE(SUBSTITUTE(SUBSTITUTE(W25," - ","_")," ","_"),"-","_"),".",""))
A26: 240 Al - MX | B26: 473 | C26: 0.163 | D26: 0.0903 | E26: 0.00403 | F26: 1.2821 | G26: =IF(OR(A26="13 Al - DX",A26="13 Al - TX",A26="13 Al - QX",A26="21 Al - QX",A26="53 Al - QX"),70,90) | H26: =G26-30 | I26: =IFERROR(B26/H26,0) | J26: QT_MTTR3 | K26: =QT_MT+K24 | W26: =INDEX(CABOS[CONDUTORES],25) | X26: =IF(ISNUMBER(FIND(" Cu",W26)),"CU",IF(ISNUMBER(FIND(" Al",W26)),"AL",IF(ISNUMBER(FIND(" AA",W26)),"AA","OUTRO"))) | Y26: =UPPER(SUBSTITUTE(SUBSTITUTE(SUBSTITUTE(SUBSTITUTE(W26," - ","_")," ","_"),"-","_"),".",""))
P27: km construido | Q27: cusot final
N28: Rede Com Estrutura | O28: BT | S28: CUSTO
N29: Cabo 53 mm² CA – Nu e PVC | O29: 56371.129 | Q29: =P29*O29 | S29: =SUM(Q29:Q58)
A30: Área (m²) | B30: kVA | C30: QTD Clientes | D30: Fator por área | E30: Fator Diversificação | F30: Demanda (KVA) | N30: Cabo 201 mm² CA - Nu e PVC | O30: 110481.13 | Q30: =P30*O30
A31: 20 | B31: 1.62 | C31: 1 | D31: =RAMAL!AB35 | E31: 3.88 | F31: =D31*E31 | N31: Cabo 70 mm² CA MMX | O31: 68591.91 | Q31: =P31*O31
A32: 21 | B32: 1.62 | C32: 2 | D32: =D31 | E32: 3.88 | F32: =D32*E32 | N32: Cabo 185 mm² CA MMX | O32: 94961.91 | Q32: =P32*O32
A33: 22 | B33: 1.62 | C33: 3 | D33: =D32 | E33: 3.88 | F33: =D33*E33 | N33: Cabo 240 mm² CA MMX | O33: 110011.91 | Q33: =P33*O33
A34: 23 | B34: 1.62 | C34: 4 | D34: =D33 | E34: 3.88 | F34: =D34*E34
A35: 24 | B35: 1.62 | C35: 5 | D35: =D34 | E35: 4.84 | F35: =D35*E35 | N35: Rede Cabo Armado | Q35: =P35*O35
A36: 25 | B36: 1.62 | C36: 6 | D36: =D35 | E36: 5.8 | F36: =D36*E36 | N36: Cabo armado 3X1X50 mm²+35 mm² | O36: 102973.3 | Q36: =P36*O36
A37: 26 | B37: 1.62 | C37: 7 | D37: =D36 | E37: 6.76 | F37: =D37*E37 | N37: Cabo armado 3X1X95 mm²+50 mm² | O37: 122163.3 | Q37: =P37*O37
A38: 27 | B38: 1.62 | C38: 8 | D38: =D37 | E38: 7.72 | F38: =D38*E38 | N38: Cabo armado 3X1X240 mm²+120 mm² | O38: 163793.3 | Q38: =P38*O38
A39: 28 | B39: 1.62 | C39: 9 | D39: =D38 | E39: 8.68 | F39: =D39*E39 | O39: TRAFO
A40: 29 | B40: 1.62 | C40: 10 | D40: =D39 | E40: 9.64 | F40: =D40*E40 | N40: Trafo Aéreo 45 kVA – Trifásico – 25,6 kV – Convencional ( Unidade ) | O40: 15780.16 | Q40: =P40*O40
...

Sheet COORDENADAS
C2: PONTO | D2: X | E2: Y
C3: 1 | D3: 635806 | E3: 7462003 | H3: 23K 635806 7462003
C4: 2 | D4: 635842 | E4: 7466204
C5: 3 | D5: 635871 | E5: 7462013
C6: 4 | D6: 635902 | E6: 746233
C7: 5 | D7: 635921 | E7: 7462020
C8: 6 | D8: 635940 | E8: 7462012
C9: 7 | D9: 635958 | E9: 7462020
C10: 8 | D10: 635985 | E10: 7462040
C11: 9 | D11: 63613 | E11: 7462062
C12: 10 | D12: 635924 | E12: 7462060
C13: 11 | D13: 635957 | E13: 7462079
C14: 12 | D14: 635986 | E14: 7462112
C15: 13 | D15: 636017 | E15: 7462129
... C17: 15 | D17: 636075 | E17: 7462174
C18: 16
C19: 17
C20: 18
C21: 19
C22: 20
C23: 21
C24: 22
C25: 23
C26: 24
C27: 25
C28: 26
C29: 27
... C63: 60

Sheet SUGESTAO_CORTES
A1: PAINEL DE SUGESTAO DE CORTES (HEURISTICO) | K1: PARAMETROS SCORE
K2: Peso carga acumulada | L2: 0.4
A3: Arquivo analisado | D3: Cenario 2 trafos | K3: Peso QT | L3: 0.35
A4: Gerado em | D4: ESQ | E4: =SUMIFS(GERAL[TOTAL DO TRECHO],GERAL[LADO],"ESQUERDO") | F4: =IF(E4*1.15<=30,30,IF(E4*1.15<=45,45,IF(E4*1.15<=75,75,IF(E4*1.15<=112.5,112.5,IF(E4*1.15<=150,150,IF(E4*1.15<=225,225,300)))))) | G4: =IFERROR(E4/F4,0) | K4: Peso balanceamento | L4: 0.2
A5: Demanda atual (kVA) | B5: =DB!K7 | D5: DIR | E5: =SUMIFS(GERAL[TOTAL DO TRECHO],GERAL[LADO],"DIREITO") | F5: =IF(E5*1.15<=30,30,IF(E5*1.15<=45,45,IF(E5*1.15<=75,75,IF(E5*1.15<=112.5,112.5,IF(E5*1.15<=150,150,IF(E5*1.15<=225,225,300)))))) | G5: =IFERROR(E5/F5,0) | K5: Penalidade distancia | L5: 0.05
A6: Trafo atual (kVA) | B6: =DB!K6 | D6: Status | E6: =IF(AND(G4<=0.85,G5<=0.85),"OK","SPLIT_MAIOR_LADO") | K6: Penalidade saturacao | L6: 0.3
A7: Saturacao atual | B7: =IFERROR(B5/B6,0) | K7: Limite sat pos-corte | L7: 0.85
B8: =IFERROR(MINIFS(GERAL[SNAP],GERAL[LADO],"ESQUERDO"),0) | E8: =IFERROR(MINIFS(GERAL[SNAP],GERAL[LADO],"DIREITO"),0) | K8: Soma pesos (ideal 1,00) | L8: =L2+L3+L4
B9: =IFERROR(MAXIFS(GERAL[SNAP],GERAL[LADO],"ESQUERDO"),1) | E9: =IFERROR(MAXIFS(GERAL[SNAP],GERAL[LADO],"DIREITO"),1)
A10: LADO ESQUERDO - TOP CORTES
A11: TOTAL_LADO_KVA | B11: =E4 | C11: MAX_QT | D11: =IFERROR(MAX(Tabela7[QT %]),0)
A13: RANK | B13: PONTO | C13: SUB_KVA | D13: REM_KVA | E13: CAP_SUG | F13: SAT_NOVA | G13: QT_PONTO | H13: BAL | I13: DIST_NORM | J13: SCORE
A14: 1 | B14: =IF($J14="","",INDEX($M$14:$M$200,MATCH($J14,$U$14:$U$200,0))) | C14: =IF($J14="","",INDEX($N$14:$N$200,MATCH($J14,$U$14:$U$200,0))) | D14: =IF($J14="","",INDEX($O$14:$O$200,MATCH($J14,$U$14:$U$200,0))) | E14: =IF($J14="","",INDEX($P$14:$P$200,MATCH($J14,$U$14:$U$200,0))) | F14: =IF($J14="","",INDEX($Q$14:$Q$200,MATCH($J14,$U$14:$U$200,0))) | G14: =IF($J14="","",INDEX($R$14:$R$200,MATCH($J14,$U$14:$U$200,0))) | H14: =IF($J14="","",INDEX($S$14:$S$200,MATCH($J14,$U$14:$U$200,0))) | I14: =IF($J14="","",INDEX($T$14:$T$200,MATCH($J14,$U$14:$U$200,0))) | J14: =IFERROR(LARGE($U$14:$U$200,1),"") | M14: =IFERROR(INDEX(GERAL[PONTO],1),"") | N14: =IF(M14="","",IFERROR(INDEX(GERAL[ACUMULADA],1),0)) | O14: =IF(N14="","",$B$11-N14) | P14: =IF(N14="","",IF(N14*1.15<=30,30,IF(N14*1.15<=45,45,IF(N14*1.15<=75,75,IF(N14*1.15<=112.5,112.5,IF(N14*1.15<=150,150,IF(N14*1.15<=225,225,300))))))) | Q14: =IF(P14="","",IFERROR(N14/P14,0)) | R14: =IF(M14="","",IFERROR(INDEX(Tabela7[QT %],MATCH(M14,Tabela7[PONTO],0)),0)) | S14: =IF(N14="","",IFERROR(1-ABS(N14-O14)/$B$11,0)) | T14: =IF(M14="","",IF($B$9>$B$8,IFERROR((INDEX(GERAL[SNAP],1)-$B$8)/($B$9-$B$8),0),0)) | U14: =IF(OR(M14="",V14<>"ESQUERDO"),"",$L$2*IFERROR(N14/$B$11,0)+$L$3*IF($D$11>0,IFERROR(R14/$D$11,0),0)+$L$4*IFERROR(S14,0)-$L$5*IFERROR(T14,0)-$L$6*MAX(0,IFERROR(Q14,0)-$L$7)+ROW()/1000000) | V14: =IFERROR(INDEX(GERAL[LADO],1),"")
A15: 2 | B15: =IF($J15="","",INDEX($M$14:$M$200,MATCH($J15,$U$14:$U$200,0))) | C15: =IF($J15="","",INDEX($N$14:$N$200,MATCH($J15,$U$14:$U$200,0))) | D15: =IF($J15="","",INDEX($O$14:$O$200,MATCH($J15,$U$14:$U$200,0))) | E15: =IF($J15="","",INDEX($P$14:$P$200,MATCH($J15,$U$14:$U$200,0))) | F15: =IF($J15="","",INDEX($Q$14:$Q$200,MATCH($J15,$U$14:$U$200,0))) | G15: =IF($J15="","",INDEX($R$14:$R$200,MATCH($J15,$U$14:$U$200,0))) | H15: =IF($J15="","",INDEX($S$14:$S$200,MATCH($J15,$U$14:$U$200,0))) | I15: =IF($J15="","",INDEX($T$14:$T$200,MATCH($J15,$U$14:$U$200,0))) | J15: =IFERROR(LARGE($U$14:$U$200,2),"") | M15: =IFERROR(INDEX(GERAL[PONTO],2),"") | N15: =IF(M15="","",IFERROR(INDEX(GERAL[ACUMULADA],2),0)) | O15: =IF(N15="","",$B$11-N15) | P15: =IF(N15="","",IF(N15*1.15<=30,30,IF(N15*1.15<=45,45,IF(N15*1.15<=75,75,IF(N15*1.15<=112.5,112.5,IF(N15*1.15<=150,150,IF(N15*1.15<=225,225,300))))))) | Q15: =IF(P15="","",IFERROR(N15/P15,0)) | R15: =IF(M15="","",IFERROR(INDEX(Tabela7[QT %],MATCH(M15,Tabela7[PONTO],0)),0)) | S15: =IF(N15="","",IFERROR(1-ABS(N15-O15)/$B$11,0)) | T15: =IF(M15="","",IF($B$9>$B$8,IFERROR((INDEX(GERAL[SNAP],2)-$B$8)/($B$9-$B$8),0),0)) | U15: =IF(OR(M15="",V15<>"ESQUERDO"),"",$L$2*IFERROR(N15/$B$11,0)+$L$3*IF($D$11>0,IFERROR(R15/$D$11,0),0)+$L$4*IFERROR(S15,0)-$L$5*IFERROR(T15,0)-$L$6*MAX(0,IFERROR(Q15,0)-$L$7)+ROW()/1000000) | V15: =IFERROR(INDEX(GERAL[LADO],2),"")
A16: 3 | B16: =IF($J16="","",INDEX($M$14:$M$200,MATCH($J16,$U$14:$U$200,0))) | C16: =IF($J16="","",INDEX($N$14:$N$200,MATCH($J16,$U$14:$U$200,0))) | D16: =IF($J16="","",INDEX($O$14:$O$200,MATCH($J16,$U$14:$U$200,0))) | E16: =IF($J16="","",INDEX($P$14:$P$200,MATCH($J16,$U$14:$U$200,0))) | F16: =IF($J16="","",INDEX($Q$14:$Q$200,MATCH($J16,$U$14:$U$200,0))) | G16: =IF($J16="","",INDEX($R$14:$R$200,MATCH($J16,$U$14:$U$200,0))) | H16: =IF($J16="","",INDEX($S$14:$S$200,MATCH($J16,$U$14:$U$200,0))) | I16: =IF($J16="","",INDEX($T$14:$T$200,MATCH($J16,$U$14:$U$200,0))) | J16: =IFERROR(LARGE($U$14:$U$200,3),"") | M16: =IFERROR(INDEX(GERAL[PONTO],3),"") | N16: =IF(M16="","",IFERROR(INDEX(GERAL[ACUMULADA],3),0)) | O16: =IF(N16="","",$B$11-N16) | P16: =IF(N16="","",IF(N16*1.15<=30,30,IF(N16*1.15<=45,45,IF(N16*1.15<=75,75,IF(N16*1.15<=112.5,112.5,IF(N16*1.15<=150,150,IF(N16*1.15<=225,225,300))))))) | Q16: =IF(P16="","",IFERROR(N16/P16,0)) | R16: =IF(M16="","",IFERROR(INDEX(Tabela7[QT %],MATCH(M16,Tabela7[PONTO],0)),0)) | S16: =IF(N16="","",IFERROR(1-ABS(N16-O16)/$B$11,0)) | T16: =IF(M16="","",IF($B$9>$B$8,IFERROR((INDEX(GERAL[SNAP],3)-$B$8)/($B$9-$B$8),0),0)) | U16: =IF(OR(M16="",V16<>"ESQUERDO"),"",$L$2*IFERROR(N16/$B$11,0)+$L$3*IF($D$11>0,IFERROR(R16/$D$11,0),0)+$L$4*IFERROR(S16,0)-$L$5*IFERROR(T16,0)-$L$6*MAX(0,IFERROR(Q16,0)-$L$7)+ROW()/1000000) | V16: =IFERROR(INDEX(GERAL[LADO],3),"")
A17: 4 | B17: =IF($J17="","",INDEX($M$14:$M$200,MATCH($J17,$U$14:$U$200,0))) | C17: =IF($J17="","",INDEX($N$14:$N$200,MATCH($J17,$U$14:$U$200,0))) | D17: =IF($J17="","",INDEX($O$14:$O$200,MATCH($J17,$U$14:$U$200,0))) | E17: =IF($J17="","",INDEX($P$14:$P$200,MATCH($J17,$U$14:$U$200,0))) | F17: =IF($J17="","",INDEX($Q$14:$Q$200,MATCH($J17,$U$14:$U$200,0))) | G17: =IF($J17="","",INDEX($R$14:$R$200,MATCH($J17,$U$14:$U$200,0))) | H17: =IF($J17="","",INDEX($S$14:$S$200,MATCH($J17,$U$14:$U$200,0))) | I17: =IF($J17="","",INDEX($T$14:$T$200,MATCH($J17,$U$14:$U$200,0))) | J17: =IFERROR(LARGE($U$14:$U$200,4),"") | M17: =IFERROR(INDEX(GERAL[PONTO],4),"") | N17: =IF(M17="","",IFERROR(INDEX(GERAL[ACUMULADA],4),0)) | O17: =IF(N17="","",$B$11-N17) | P17: =IF(N17="","",IF(N17*1.15<=30,30,IF(N17*1.15<=45,45,IF(N17*1.15<=75,75,IF(N17*1.15<=112.5,112.5,IF(N17*1.15<=150,150,IF(N17*1.15<=225,225,300))))))) | Q17: =IF(P17="","",IFERROR(N17/P17,0)) | R17: =IF(M17="","",IFERROR(INDEX(Tabela7[QT %],MATCH(M17,Tabela7[PONTO],0)),0)) | S17: =IF(N17="","",IFERROR(1-ABS(N17-O17)/$B$11,0)) | T17: =IF(M17="","",IF($B$9>$B$8,IFERROR((INDEX(GERAL[SNAP],4)-$B$8)/($B$9-$B$8),0),0)) | U17: =IF(OR(M17="",V17<>"ESQUERDO"),"",$L$2*IFERROR(N17/$B$11,0)+$L$3*IF($D$11>0,IFERROR(R17/$D$11,0),0)+$L$4*IFERROR(S17,0)-$L$5*IFERROR(T17,0)-$L$6*MAX(0,IFERROR(Q17,0)-$L$7)+ROW()/1000000) | V17: =IFERROR(INDEX(GERAL[LADO],4),"")
A18: 5 | B18: =IF($J18="","",INDEX($M$14:$M$200,MATCH($J18,$U$14:$U$200,0))) | C18: =IF($J18="","",INDEX($N$14:$N$200,MATCH($J18,$U$14:$U$200,0))) | D18: =IF($J18="","",INDEX($O$14:$O$200,MATCH($J18,$U$14:$U$200,0))) | E18: =IF($J18="","",INDEX($P$14:$P$200,MATCH($J18,$U$14:$U$200,0))) | F18: =IF($J18="","",INDEX($Q$14:$Q$200,MATCH($J18,$U$14:$U$200,0))) | G18: =IF($J18="","",INDEX($R$14:$R$200,MATCH($J18,$U$14:$U$200,0))) | H18: =IF($J18="","",INDEX($S$14:$S$200,MATCH($J18,$U$14:$U$200,0))) | I18: =IF($J18="","",INDEX($T$14:$T$200,MATCH($J18,$U$14:$U$200,0))) | J18: =IFERROR(LARGE($U$14:$U$200,5),"") | M18: =IFERROR(INDEX(GERAL[PONTO],5),"") | N18: =IF(M18="","",IFERROR(INDEX(GERAL[ACUMULADA],5),0)) | O18: =IF(N18="","",$B$11-N18) | P18: =IF(N18="","",IF(N18*1.15<=30,30,IF(N18*1.15<=45,45,IF(N18*1.15<=75,75,IF(N18*1.15<=112.5,112.5,IF(N18*1.15<=150,150,IF(N18*1.15<=225,225,300))))))) | Q18: =IF(P18="","",IFERROR(N18/P18,0)) | R18: =IF(M18="","",IFERROR(INDEX(Tabela7[QT %],MATCH(M18,Tabela7[PONTO],0)),0)) | S18: =IF(N18="","",IFERROR(1-ABS(N18-O18)/$B$11,0)) | T18: =IF(M18="","",IF($B$9>$B$8,IFERROR((INDEX(GERAL[SNAP],5)-$B$8)/($B$9-$B$8),0),0)) | U18: =IF(OR(M18="",V18<>"ESQUERDO"),"",$L$2*IFERROR(N18/$B$11,0)+$L$3*IF($D$11>0,IFERROR(R18/$D$11,0),0)+$L$4*IFERROR(S18,0)-$L$5*IFERROR(T18,0)-$L$6*MAX(0,IFERROR(Q18,0)-$L$7)+ROW()/1000000) | V18: =IFERROR(INDEX(GERAL[LADO],5),"")
A19: 6 | B19: =IF($J19="","",INDEX($M$14:$M$200,MATCH($J19,$U$14:$U$200,0))) | C19: =IF($J19="","",INDEX($N$14:$N$200,MATCH($J19,$U$14:$U$200,0))) | D19: =IF($J19="","",INDEX($O$14:$O$200,MATCH($J19,$U$14:$U$200,0))) | E19: =IF($J19="","",INDEX($P$14:$P$200,MATCH($J19,$U$14:$U$200,0))) | F19: =IF($J19="","",INDEX($Q$14:$Q$200,MATCH($J19,$U$14:$U$200,0))) | G19: =IF($J19="","",INDEX($R$14:$R$200,MATCH($J19,$U$14:$U$200,0))) | H19: =IF($J19="","",INDEX($S$14:$S$200,MATCH($J19,$U$14:$U$200,0))) | I19: =IF($J19="","",INDEX($T$14:$T$200,MATCH($J19,$U$14:$U$200,0))) | J19: =IFERROR(LARGE($U$14:$U$200,6),"") | M19: =IFERROR(INDEX(GERAL[PONTO],6),"") | N19: =IF(M19="","",IFERROR(INDEX(GERAL[ACUMULADA],6),0)) | O19: =IF(N19="","",$B$11-N19) | P19: =IF(N19="","",IF(N19*1.15<=30,30,IF(N19*1.15<=45,45,IF(N19*1.15<=75,75,IF(N19*1.15<=112.5,112.5,IF(N19*1.15<=150,150,IF(N19*1.15<=225,225,300))))))) | Q19: =IF(P19="","",IFERROR(N19/P19,0)) | R19: =IF(M19="","",IFERROR(INDEX(Tabela7[QT %],MATCH(M19,Tabela7[PONTO],0)),0)) | S19: =IF(N19="","",IFERROR(1-ABS(N19-O19)/$B$11,0)) | T19: =IF(M19="","",IF($B$9>$B$8,IFERROR((INDEX(GERAL[SNAP],6)-$B$8)/($B$9-$B$8),0),0)) | U19: =IF(OR(M19="",V19<>"ESQUERDO"),"",$L$2*IFERROR(N19/$B$11,0)+$L$3*IF($D$11>0,IFERROR(R19/$D$11,0),0)+$L$4*IFERROR(S19,0)-$L$5*IFERROR(T19,0)-$L$6*MAX(0,IFERROR(Q19,0)-$L$7)+ROW()/1000000) | V19: =IFERROR(INDEX(GERAL[LADO],6),"")
A20: 7 | B20: =IF($J20="","",INDEX($M$14:$M$200,MATCH($J20,$U$14:$U$200,0))) | C20: =IF($J20="","",INDEX($N$14:$N$200,MATCH($J20,$U$14:$U$200,0))) | D20: =IF($J20="","",INDEX($O$14:$O$200,MATCH($J20,$U$14:$U$200,0))) | E20: =IF($J20="","",INDEX($P$14:$P$200,MATCH($J20,$U$14:$U$200,0))) | F20: =IF($J20="","",INDEX($Q$14:$Q$200,MATCH($J20,$U$14:$U$200,0))) | G20: =IF($J20="","",INDEX($R$14:$R$200,MATCH($J20,$U$14:$U$200,0))) | H20: =IF($J20="","",INDEX($S$14:$S$200,MATCH($J20,$U$14:$U$200,0))) | I20: =IF($J20="","",INDEX($T$14:$T$200,MATCH($J20,$U$14:$U$200,0))) | J20: =IFERROR(LARGE($U$14:$U$200,7),"") | M20: =IFERROR(INDEX(GERAL[PONTO],7),"") | N20: =IF(M20="","",IFERROR(INDEX(GERAL[ACUMULADA],7),0)) | O20: =IF(N20="","",$B$11-N20) | P20: =IF(N20="","",IF(N20*1.15<=30,30,IF(N20*1.15<=45,45,IF(N20*1.15<=75,75,IF(N20*1.15<=112.5,112.5,IF(N20*1.15<=150,150,IF(N20*1.15<=225,225,300))))))) | Q20: =IF(P20="","",IFERROR(N20/P20,0)) | R20: =IF(M20="","",IFERROR(INDEX(Tabela7[QT %],MATCH(M20,Tabela7[PONTO],0)),0)) | S20: =IF(N20="","",IFERROR(1-ABS(N20-O20)/$B$11,0)) | T20: =IF(M20="","",IF($B$9>$B$8,IFERROR((INDEX(GERAL[SNAP],7)-$B$8)/($B$9-$B$8),0),0)) | U20: =IF(OR(M20="",V20<>"ESQUERDO"),"",$L$2*IFERROR(N20/$B$11,0)+$L$3*IF($D$11>0,IFERROR(R20/$D$11,0),0)+$L$4*IFERROR(S20,0)-$L$5*IFERROR(T20,0)-$L$6*MAX(0,IFERROR(Q20,0)-$L$7)+ROW()/1000000) | V20: =IFERROR(INDEX(GERAL[LADO],7),"")
A21: 8 | B21: =IF($J21="","",INDEX($M$14:$M$200,MATCH($J21,$U$14:$U$200,0))) | C21: =IF($J21="","",INDEX($N$14:$N$200,MATCH($J21,$U$14:$U$200,0))) | D21: =IF($J21="","",INDEX($O$14:$O$200,MATCH($J21,$U$14:$U$200,0))) | E21: =IF($J21="","",INDEX($P$14:$P$200,MATCH($J21,$U$14:$U$200,0))) | F21: =IF($J21="","",INDEX($Q$14:$Q$200,MATCH($J21,$U$14:$U$200,0))) | G21: =IF($J21="","",INDEX($R$14:$R$200,MATCH($J21,$U$14:$U$200,0))) | H21: =IF($J21="","",INDEX($S$14:$S$200,MATCH($J21,$U$14:$U$200,0))) | I21: =IF($J21="","",INDEX($T$14:$T$200,MATCH($J21,$U$14:$U$200,0))) | J21: =IFERROR(LARGE($U$14:$U$200,8),"") | M21: =IFERROR(INDEX(GERAL[PONTO],8),"") | N21: =IF(M21="","",IFERROR(INDEX(GERAL[ACUMULADA],8),0)) | O21: =IF(N21="","",$B$11-N21) | P21: =IF(N21="","",IF(N21*1.15<=30,30,IF(N21*1.15<=45,45,IF(N21*1.15<=75,75,IF(N21*1.15<=112.5,112.5,IF(N21*1.15<=150,150,IF(N21*1.15<=225,225,300))))))) | Q21: =IF(P21="","",IFERROR(N21/P21,0)) | R21: =IF(M21="","",IFERROR(INDEX(Tabela7[QT %],MATCH(M21,Tabela7[PONTO],0)),0)) | S21: =IF(N21="","",IFERROR(1-ABS(N21-O21)/$B$11,0)) | T21: =IF(M21="","",IF($B$9>$B$8,IFERROR((INDEX(GERAL[SNAP],8)-$B$8)/($B$9-$B$8),0),0)) | U21: =IF(OR(M21="",V21<>"ESQUERDO"),"",$L$2*IFERROR(N21/$B$11,0)+$L$3*IF($D$11>0,IFERROR(R21/$D$11,0),0)+$L$4*IFERROR(S21,0)-$L$5*IFERROR(T21,0)-$L$6*MAX(0,IFERROR(Q21,0)-$L$7)+ROW()/1000000) | V21: =IFERROR(INDEX(GERAL[LADO],8),"")
A22: 9 | B22: =IF($J22="","",INDEX($M$14:$M$200,MATCH($J22,$U$14:$U$200,0))) | C22: =IF($J22="","",INDEX($N$14:$N$200,MATCH($J22,$U$14:$U$200,0))) | D22: =IF($J22="","",INDEX($O$14:$O$200,MATCH($J22,$U$14:$U$200,0))) | E22: =IF($J22="","",INDEX($P$14:$P$200,MATCH($J22,$U$14:$U$200,0))) | F22: =IF($J22="","",INDEX($Q$14:$Q$200,MATCH($J22,$U$14:$U$200,0))) | G22: =IF($J22="","",INDEX($R$14:$R$200,MATCH($J22,$U$14:$U$200,0))) | H22: =IF($J22="","",INDEX($S$14:$S$200,MATCH($J22,$U$14:$U$200,0))) | I22: =IF($J22="","",INDEX($T$14:$T$200,MATCH($J22,$U$14:$U$200,0))) | J22: =IFERROR(LARGE($U$14:$U$200,9),"") | M22: =IFERROR(INDEX(GERAL[PONTO],9),"") | N22: =IF(M22="","",IFERROR(INDEX(GERAL[ACUMULADA],9),0)) | O22: =IF(N22="","",$B$11-N22) | P22: =IF(N22="","",IF(N22*1.15<=30,30,IF(N22*1.15<=45,45,IF(N22*1.15<=75,75,IF(N22*1.15<=112.5,112.5,IF(N22*1.15<=150,150,IF(N22*1.15<=225,225,300))))))) | Q22: =IF(P22="","",IFERROR(N22/P22,0)) | R22: =IF(M22="","",IFERROR(INDEX(Tabela7[QT %],MATCH(M22,Tabela7[PONTO],0)),0)) | S22: =IF(N22="","",IFERROR(1-ABS(N22-O22)/$B$11,0)) | T22: =IF(M22="","",IF($B$9>$B$8,IFERROR((INDEX(GERAL[SNAP],9)-$B$8)/($B$9-$B$8),0),0)) | U22: =IF(OR(M22="",V22<>"ESQUERDO"),"",$L$2*IFERROR(N22/$B$11,0)+$L$3*IF($D$11>0,IFERROR(R22/$D$11,0),0)+$L$4*IFERROR(S22,0)-$L$5*IFERROR(T22,0)-$L$6*MAX(0,IFERROR(Q22,0)-$L$7)+ROW()/1000000) | V22: =IFERROR(INDEX(GERAL[LADO],9),"")
A23: 10 | B23: =IF($J23="","",INDEX($M$14:$M$200,MATCH($J23,$U$14:$U$200,0))) | C23: =IF($J23="","",INDEX($N$14:$N$200,MATCH($J23,$U$14:$U$200,0))) | D23: =IF($J23="","",INDEX($O$14:$O$200,MATCH($J23,$U$14:$U$200,0))) | E23: =IF($J23="","",INDEX($P$14:$P$200,MATCH($J23,$U$14:$U$200,0))) | F23: =IF($J23="","",INDEX($Q$14:$Q$200,MATCH($J23,$U$14:$U$200,0))) | G23: =IF($J23="","",INDEX($R$14:$R$200,MATCH($J23,$U$14:$U$200,0))) | H23: =IF($J23="","",INDEX($S$14:$S$200,MATCH($J23,$U$14:$U$200,0))) | I23: =IF($J23="","",INDEX($T$14:$T$200,MATCH($J23,$U$14:$U$200,0))) | J23: =IFERROR(LARGE($U$14:$U$200,10),"") | M23: =IFERROR(INDEX(GERAL[PONTO],10),"") | N23: =IF(M23="","",IFERROR(INDEX(GERAL[ACUMULADA],10),0)) | O23: =IF(N23="","",$B$11-N23) | P23: =IF(N23="","",IF(N23*1.15<=30,30,IF(N23*1.15<=45,45,IF(N23*1.15<=75,75,IF(N23*1.15<=112.5,112.5,IF(N23*1.15<=150,150,IF(N23*1.15<=225,225,300))))))) | Q23: =IF(P23="","",IFERROR(N23/P23,0)) | R23: =IF(M23="","",IFERROR(INDEX(Tabela7[QT %],MATCH(M23,Tabela7[PONTO],0)),0)) | S23: =IF(N23="","",IFERROR(1-ABS(N23-O23)/$B$11,0)) | T23: =IF(M23="","",IF($B$9>$B$8,IFERROR((INDEX(GERAL[SNAP],10)-$B$8)/($B$9-$B$8),0),0)) | U23: =IF(OR(M23="",V23<>"ESQUERDO"),"",$L$2*IFERROR(N23/$B$11,0)+$L$3*IF($D$11>0,IFERROR(R23/$D$11,0),0)+$L$4*IFERROR(S23,0)-$L$5*IFERROR(T23,0)-$L$6*MAX(0,IFERROR(Q23,0)-$L$7)+ROW()/1000000) | V23: =IFERROR(INDEX(GERAL[LADO],10),"")
A24: 11 | B24: =IF($J24="","",INDEX($M$14:$M$200,MATCH($J24,$U$14:$U$200,0))) | C24: =IF($J24="","",INDEX($N$14:$N$200,MATCH($J24,$U$14:$U$200,0))) | D24: =IF($J24="","",INDEX($O$14:$O$200,MATCH($J24,$U$14:$U$200,0))) | E24: =IF($J24="","",INDEX($P$14:$P$200,MATCH($J24,$U$14:$U$200,0))) | F24: =IF($J24="","",INDEX($Q$14:$Q$200,MATCH($J24,$U$14:$U$200,0))) | G24: =IF($J24="","",INDEX($R$14:$R$200,MATCH($J24,$U$14:$U$200,0))) | H24: =IF($J24="","",INDEX($S$14:$S$200,MATCH($J24,$U$14:$U$200,0))) | I24: =IF($J24="","",INDEX($T$14:$T$200,MATCH($J24,$U$14:$U$200,0))) | J24: =IFERROR(LARGE($U$14:$U$200,11),"") | M24: =IFERROR(INDEX(GERAL[PONTO],11),"") | N24: =IF(M24="","",IFERROR(INDEX(GERAL[ACUMULADA],11),0)) | O24: =IF(N24="","",$B$11-N24) | P24: =IF(N24="","",IF(N24*1.15<=30,30,IF(N24*1.15<=45,45,IF(N24*1.15<=75,75,IF(N24*1.15<=112.5,112.5,IF(N24*1.15<=150,150,IF(N24*1.15<=225,225,300))))))) | Q24: =IF(P24="","",IFERROR(N24/P24,0)) | R24: =IF(M24="","",IFERROR(INDEX(Tabela7[QT %],MATCH(M24,Tabela7[PONTO],0)),0)) | S24: =IF(N24="","",IFERROR(1-ABS(N24-O24)/$B$11,0)) | T24: =IF(M24="","",IF($B$9>$B$8,IFERROR((INDEX(GERAL[SNAP],11)-$B$8)/($B$9-$B$8),0),0)) | U24: =IF(OR(M24="",V24<>"ESQUERDO"),"",$L$2*IFERROR(N24/$B$11,0)+$L$3*IF($D$11>0,IFERROR(R24/$D$11,0),0)+$L$4*IFERROR(S24,0)-$L$5*IFERROR(T24,0)-$L$6*MAX(0,IFERROR(Q24,0)-$L$7)+ROW()/1000000) | V24: =IFERROR(INDEX(GERAL[LADO],11),"")
A25: 12 | B25: =IF($J25="","",INDEX($M$14:$M$200,MATCH($J25,$U$14:$U$200,0))) | C25: =IF($J25="","",INDEX($N$14:$N$200,MATCH($J25,$U$14:$U$200,0))) | D25: =IF($J25="","",INDEX($O$14:$O$200,MATCH($J25,$U$14:$U$200,0))) | E25: =IF($J25="","",INDEX($P$14:$P$200,MATCH($J25,$U$14:$U$200,0))) | F25: =IF($J25="","",INDEX($Q$14:$Q$200,MATCH($J25,$U$14:$U$200,0))) | G25: =IF($J25="","",INDEX($R$14:$R$200,MATCH($J25,$U$14:$U$200,0))) | H25: =IF($J25="","",INDEX($S$14:$S$200,MATCH($J25,$U$14:$U$200,0))) | I25: =IF($J25="","",INDEX($T$14:$T$200,MATCH($J25,$U$14:$U$200,0))) | J25: =IFERROR(LARGE($U$14:$U$200,12),"") | M25: =IFERROR(INDEX(GERAL[PONTO],12),"") | N25: =IF(M25="","",IFERROR(INDEX(GERAL[ACUMULADA],12),0)) | O25: =IF(N25="","",$B$11-N25) | P25: =IF(N25="","",IF(N25*1.15<=30,30,IF(N25*1.15<=45,45,IF(N25*1.15<=75,75,IF(N25*1.15<=112.5,112.5,IF(N25*1.15<=150,150,IF(N25*1.15<=225,225,300))))))) | Q25: =IF(P25="","",IFERROR(N25/P25,0)) | R25: =IF(M25="","",IFERROR(INDEX(Tabela7[QT %],MATCH(M25,Tabela7[PONTO],0)),0)) | S25: =IF(N25="","",IFERROR(1-ABS(N25-O25)/$B$11,0)) | T25: =IF(M25="","",IF($B$9>$B$8,IFERROR((INDEX(GERAL[SNAP],12)-$B$8)/($B$9-$B$8),0),0)) | U25: =IF(OR(M25="",V25<>"ESQUERDO"),"",$L$2*IFERROR(N25/$B$11,0)+$L$3*IF($D$11>0,IFERROR(R25/$D$11,0),0)+$L$4*IFERROR(S25,0)-$L$5*IFERROR(T25,0)-$L$6*MAX(0,IFERROR(Q25,0)-$L$7)+ROW()/1000000) | V25: =IFERROR(INDEX(GERAL[LADO],12),"")
M26: =IFERROR(INDEX(GERAL[PONTO],13),"") | N26: =IF(M26="","",IFERROR(INDEX(GERAL[ACUMULADA],13),0)) | O26: =IF(N26="","",$B$11-N26) | P26: =IF(N26="","",IF(N26*1.15<=30,30,IF(N26*1.15<=45,45,IF(N26*1.15<=75,75,IF(N26*1.15<=112.5,112.5,IF(N26*1.15<=150,150,IF(N26*1.15<=225,225,300))))))) | Q26: =IF(P26="","",IFERROR(N26/P26,0)) | R26: =IF(M26="","",IFERROR(INDEX(Tabela7[QT %],MATCH(M26,Tabela7[PONTO],0)),0)) | S26: =IF(N26="","",IFERROR(1-ABS(N26-O26)/$B$11,0)) | T26: =IF(M26="","",IF($B$9>$B$8,IFERROR((INDEX(GERAL[SNAP],13)-$B$8)/($B$9-$B$8),0),0)) | U26: =IF(OR(M26="",V26<>"ESQUERDO"),"",$L$2*IFERROR(N26/$B$11,0)+$L$3*IF($D$11>0,IFERROR(R26/$D$11,0),0)+$L$4*IFERROR(S26,0)-$L$5*IFERROR(T26,0)-$L$6*MAX(0,IFERROR(Q26,0)-$L$7)+ROW()/1000000) | V26: =IFERROR(INDEX(GERAL[LADO],13),"")
M27: =IFERROR(INDEX(GERAL[PONTO],14),"") | N27: =IF(M27="","",IFERROR(INDEX(GERAL[ACUMULADA],14),0)) | O27: =IF(N27="","",$B$11-N27) | P27: =IF(N27="","",IF(N27*1.15<=30,30,IF(N27*1.15<=45,45,IF(N27*1.15<=75,75,IF(N27*1.15<=112.5,112.5,IF(N27*1.15<=150,150,IF(N27*1.15<=225,225,300))))))) | Q27: =IF(P27="","",IFERROR(N27/P27,0)) | R27: =IF(M27="","",IFERROR(INDEX(Tabela7[QT %],MATCH(M27,Tabela7[PONTO],0)),0)) | S27: =IF(N27="","",IFERROR(1-ABS(N27-O27)/$B$11,0)) | T27: =IF(M27="","",IF($B$9>$B$8,IFERROR((INDEX(GERAL[SNAP],14)-$B$8)/($B$9-$B$8),0),0)) | U27: =IF(OR(M27="",V27<>"ESQUERDO"),"",$L$2*IFERROR(N27/$B$11,0)+$L$3*IF($D$11>0,IFERROR(R27/$D$11,0),0)+$L$4*IFERROR(S27,0)-$L$5*IFERROR(T27,0)-$L$6*MAX(0,IFERROR(Q27,0)-$L$7)+ROW()/1000000) | V27: =IFERROR(INDEX(GERAL[LADO],14),"")
M28: =IFERROR(INDEX(GERAL[PONTO],15),"") | N28: =IF(M28="","",IFERROR(INDEX(GERAL[ACUMULADA],15),0)) | O28: =IF(N28="","",$B$11-N28) | P28: =IF(N28="","",IF(N28*1.15<=30,30,IF(N28*1.15<=45,45,IF(N28*1.15<=75,75,IF(N28*1.15<=112.5,112.5,IF(N28*1.15<=150,150,IF(N28*1.15<=225,225,300))))))) | Q28: =IF(P28="","",IFERROR(N28/P28,0)) | R28: =IF(M28="","",IFERROR(INDEX(Tabela7[QT %],MATCH(M28,Tabela7[PONTO],0)),0)) | S28: =IF(N28="","",IFERROR(1-ABS(N28-O28)/$B$11,0)) | T28: =IF(M28="","",IF($B$9>$B$8,IFERROR((INDEX(GERAL[SNAP],15)-$B$8)/($B$9-$B$8),0),0)) | U28: =IF(OR(M28="",V28<>"ESQUERDO"),"",$L$2*IFERROR(N28/$B$11,0)+$L$3*IF($D$11>0,IFERROR(R28/$D$11,0),0)+$L$4*IFERROR(S28,0)-$L$5*IFERROR(T28,0)-$L$6*MAX(0,IFERROR(Q28,0)-$L$7)+ROW()/1000000) | V28: =IFERROR(INDEX(GERAL[LADO],15),"")
M29: =IFERROR(INDEX(GERAL[PONTO],16),"") | N29: =IF(M29="","",IFERROR(INDEX(GERAL[ACUMULADA],16),0)) | O29: =IF(N29="","",$B$11-N29) | P29: =IF(N29="","",IF(N29*1.15<=30,30,IF(N29*1.15<=45,45,IF(N29*1.15<=75,75,IF(N29*1.15<=112.5,112.5,IF(N29*1.15<=150,150,IF(N29*1.15<=225,225,300))))))) | Q29: =IF(P29="","",IFERROR(N29/P29,0)) | R29: =IF(M29="","",IFERROR(INDEX(Tabela7[QT %],MATCH(M29,Tabela7[PONTO],0)),0)) | S29: =IF(N29="","",IFERROR(1-ABS(N29-O29)/$B$11,0)) | T29: =IF(M29="","",IF($B$9>$B$8,IFERROR((INDEX(GERAL[SNAP],16)-$B$8)/($B$9-$B$8),0),0)) | U29: =IF(OR(M29="",V29<>"ESQUERDO"),"",$L$2*IFERROR(N29/$B$11,0)+$L$3*IF($D$11>0,IFERROR(R29/$D$11,0),0)+$L$4*IFERROR(S29,0)-$L$5*IFERROR(T29,0)-$L$6*MAX(0,IFERROR(Q29,0)-$L$7)+ROW()/1000000) | V29: =IFERROR(INDEX(GERAL[LADO],16),"")
A30: LADO DIREITO - TOP CORTES | M30: =IFERROR(INDEX(GERAL[PONTO],17),"") | N30: =IF(M30="","",IFERROR(INDEX(GERAL[ACUMULADA],17),0)) | O30: =IF(N30="","",$B$11-N30) | P30: =IF(N30="","",IF(N30*1.15<=30,30,IF(N30*1.15<=45,45,IF(N30*1.15<=75,75,IF(N30*1.15<=112.5,112.5,IF(N30*1.15<=150,150,IF(N30*1.15<=225,225,300))))))) | Q30: =IF(P30="","",IFERROR(N30/P30,0)) | R30: =IF(M30="","",IFERROR(INDEX(Tabela7[QT %],MATCH(M30,Tabela7[PONTO],0)),0)) | S30: =IF(N30="","",IFERROR(1-ABS(N30-O30)/$B$11,0)) | T30: =IF(M30="","",IF($B$9>$B$8,IFERROR((INDEX(GERAL[SNAP],17)-$B$8)/($B$9-$B$8),0),0)) | U30: =IF(OR(M30="",V30<>"ESQUERDO"),"",$L$2*IFERROR(N30/$B$11,0)+$L$3*IF($D$11>0,IFERROR(R30/$D$11,0),0)+$L$4*IFERROR(S30,0)-$L$5*IFERROR(T30,0)-$L$6*MAX(0,IFERROR(Q30,0)-$L$7)+ROW()/1000000) | V30: =IFERROR(INDEX(GERAL[LADO],17),"")
A31: TOTAL_LADO_KVA | B31: =E5 | C31: MAX_QT | D31: =IFERROR(MAX(DIR_ATUAL[QT %]),0) | M31: =IFERROR(INDEX(GERAL[PONTO],18),"") | N31: =IF(M31="","",IFERROR(INDEX(GERAL[ACUMULADA],18),0)) | O31: =IF(N31="","",$B$11-N31) | P31: =IF(N31="","",IF(N31*1.15<=30,30,IF(N31*1.15<=45,45,IF(N31*1.15<=75,75,IF(N31*1.15<=112.5,112.5,IF(N31*1.15<=150,150,IF(N31*1.15<=225,225,300))))))) | Q31: =IF(P31="","",IFERROR(N31/P31,0)) | R31: =IF(M31="","",IFERROR(INDEX(Tabela7[QT %],MATCH(M31,Tabela7[PONTO],0)),0)) | S31: =IF(N31="","",IFERROR(1-ABS(N31-O31)/$B$11,0)) | T31: =IF(M31="","",IF($B$9>$B$8,IFERROR((INDEX(GERAL[SNAP],18)-$B$8)/($B$9-$B$8),0),0)) | U31: =IF(OR(M31="",V31<>"ESQUERDO"),"",$L$2*IFERROR(N31/$B$11,0)+$L$3*IF($D$11>0,IFERROR(R31/$D$11,0),0)+$L$4*IFERROR(S31,0)-$L$5*IFERROR(T31,0)-$L$6*MAX(0,IFERROR(Q31,0)-$L$7)+ROW()/1000000) | V31: =IFERROR(INDEX(GERAL[LADO],18),"")
M32: =IFERROR(INDEX(GERAL[PONTO],19),"") | N32: =IF(M32="","",IFERROR(INDEX(GERAL[ACUMULADA],19),0)) | O32: =IF(N32="","",$B$11-N32) | P32: =IF(N32="","",IF(N32*1.15<=30,30,IF(N32*1.15<=45,45,IF(N32*1.15<=75,75,IF(N32*1.15<=112.5,112.5,IF(N32*1.15<=150,150,IF(N32*1.15<=225,225,300))))))) | Q32: =IF(P32="","",IFERROR(N32/P32,0)) | R32: =IF(M32="","",IFERROR(INDEX(Tabela7[QT %],MATCH(M32,Tabela7[PONTO],0)),0)) | S32: =IF(N32="","",IFERROR(1-ABS(N32-O32)/$B$11,0)) | T32: =IF(M32="","",IF($B$9>$B$8,IFERROR((INDEX(GERAL[SNAP],19)-$B$8)/($B$9-$B$8),0),0)) | U32: =IF(OR(M32="",V32<>"ESQUERDO"),"",$L$2*IFERROR(N32/$B$11,0)+$L$3*IF($D$11>0,IFERROR(R32/$D$11,0),0)+$L$4*IFERROR(S32,0)-$L$5*IFERROR(T32,0)-$L$6*MAX(0,IFERROR(Q32,0)-$L$7)+ROW()/1000000) | V32: =IFERROR(INDEX(GERAL[LADO],19),"")
A33: RANK | B33: PONTO | C33: SUB_KVA | D33: REM_KVA | E33: CAP_SUG | F33: SAT_NOVA | G33: QT_PONTO | H33: BAL | I33: DIST_NORM | J33: SCORE | M33: =IFERROR(INDEX(GERAL[PONTO],20),"") | N33: =IF(M33="","",IFERROR(INDEX(GERAL[ACUMULADA],20),0)) | O33: =IF(N33="","",$B$11-N33) | P33: =IF(N33="","",IF(N33*1.15<=30,30,IF(N33*1.15<=45,45,IF(N33*1.15<=75,75,IF(N33*1.15<=112.5,112.5,IF(N33*1.15<=150,150,IF(N33*1.15<=225,225,300))))))) | Q33: =IF(P33="","",IFERROR(N33/P33,0)) | R33: =IF(M33="","",IFERROR(INDEX(Tabela7[QT %],MATCH(M33,Tabela7[PONTO],0)),0)) | S33: =IF(N33="","",IFERROR(1-ABS(N33-O33)/$B$11,0)) | T33: =IF(M33="","",IF($B$9>$B$8,IFERROR((INDEX(GERAL[SNAP],20)-$B$8)/($B$9-$B$8),0),0)) | U33: =IF(OR(M33="",V33<>"ESQUERDO"),"",$L$2*IFERROR(N33/$B$11,0)+$L$3*IF($D$11>0,IFERROR(R33/$D$11,0),0)+$L$4*IFERROR(S33,0)-$L$5*IFERROR(T33,0)-$L$6*MAX(0,IFERROR(Q33,0)-$L$7)+ROW()/1000000) | V33: =IFERROR(INDEX(GERAL[LADO],20),"")
A34: 1 | B34: =IF($J34="","",INDEX($X$34:$X$220,MATCH($J34,$AF$34:$AF$220,0))) | C34: =IF($J34="","",INDEX($Y$34:$Y$220,MATCH($J34,$AF$34:$AF$220,0))) | D34: =IF($J34="","",INDEX($Z$34:$Z$220,MATCH($J34,$AF$34:$AF$220,0))) | E34: =IF($J34="","",INDEX($AA$34:$AA$220,MATCH($J34,$AF$34:$AF$220,0))) | F34: =IF($J34="","",INDEX($AB$34:$AB$220,MATCH($J34,$AF$34:$AF$220,0))) | G34: =IF($J34="","",INDEX($AC$34:$AC$220,MATCH($J34,$AF$34:$AF$220,0))) | H34: =IF($J34="","",INDEX($AD$34:$AD$220,MATCH($J34,$AF$34:$AF$220,0))) | I34: =IF($J34="","",INDEX($AE$34:$AE$220,MATCH($J34,$AF$34:$AF$220,0))) | J34: =IFERROR(LARGE($AF$34:$AF$220,1),"") | M34: =IFERROR(INDEX(GERAL[PONTO],21),"") | N34: =IF(M34="","",IFERROR(INDEX(GERAL[ACUMULADA],21),0)) | O34: =IF(N34="","",$B$11-N34) | P34: =IF(N34="","",IF(N34*1.15<=30,30,IF(N34*1.15<=45,45,IF(N34*1.15<=75,75,IF(N34*1.15<=112.5,112.5,IF(N34*1.15<=150,150,IF(N34*1.15<=225,225,300))))))) | Q34: =IF(P34="","",IFERROR(N34/P34,0)) | R34: =IF(M34="","",IFERROR(INDEX(Tabela7[QT %],MATCH(M34,Tabela7[PONTO],0)),0)) | S34: =IF(N34="","",IFERROR(1-ABS(N34-O34)/$B$11,0)) | T34: =IF(M34="","",IF($B$9>$B$8,IFERROR((INDEX(GERAL[SNAP],21)-$B$8)/($B$9-$B$8),0),0)) | U34: =IF(OR(M34="",V34<>"ESQUERDO"),"",$L$2*IFERROR(N34/$B$11,0)+$L$3*IF($D$11>0,IFERROR(R34/$D$11,0),0)+$L$4*IFERROR(S34,0)-$L$5*IFERROR(T34,0)-$L$6*MAX(0,IFERROR(Q34,0)-$L$7)+ROW()/1000000) | V34: =IFERROR(INDEX(GERAL[LADO],21),"") | X34: =IFERROR(INDEX(GERAL[PONTO],1),"") | Y34: =IF(X34="","",IFERROR(INDEX(GERAL[ACUMULADA],1),0)) | Z34: =IF(Y34="","",$B$31-Y34) | AA34: =IF(Y34="","",IF(Y34*1.15<=30,30,IF(Y34*1.15<=45,45,IF(Y34*1.15<=75,75,IF(Y34*1.15<=112.5,112.5,IF(Y34*1.15<=150,150,IF(Y34*1.15<=225,225,300))))))) | AB34: =IF(AA34="","",IFERROR(Y34/AA34,0)) | AC34: =IF(X34="","",IFERROR(INDEX(DIR_ATUAL[QT %],MATCH(X34,DIR_ATUAL[PONTO],0)),0)) | AD34: =IF(Y34="","",IFERROR(1-ABS(Y34-Z34)/$B$31,0)) | AE34: =IF(X34="","",IF($E$9>$E$8,IFERROR((INDEX(GERAL[SNAP],1)-$E$8)/($E$9-$E$8),0),0)) | AF34: =IF(OR(X34="",AG34<>"DIREITO"),"",$L$2*IFERROR(Y34/$B$31,0)+$L$3*IF($D$31>0,IFERROR(AC34/$D$31,0),0)+$L$4*IFERROR(AD34,0)-$L$5*IFERROR(AE34,0)-$L$6*MAX(0,IFERROR(AB34,0)-$L$7)+ROW()/1000000) | AG34: =IFERROR(INDEX(GERAL[LADO],1),"")
A35: 2 | B35: =IF($J35="","",INDEX($X$34:$X$220,MATCH($J35,$AF$34:$AF$220,0))) | C35: =IF($J35="","",INDEX($Y$34:$Y$220,MATCH($J35,$AF$34:$AF$220,0))) | D35: =IF($J35="","",INDEX($Z$34:$Z$220,MATCH($J35,$AF$34:$AF$220,0))) | E35: =IF($J35="","",INDEX($AA$34:$AA$220,MATCH($J35,$AF$34:$AF$220,0))) | F35: =IF($J35="","",INDEX($AB$34:$AB$220,MATCH($J35,$AF$34:$AF$220,0))) | G35: =IF($J35="","",INDEX($AC$34:$AC$220,MATCH($J35,$AF$34:$AF$220,0))) | H35: =IF($J35="","",INDEX($AD$34:$AD$220,MATCH($J35,$AF$34:$AF$220,0))) | I35: =IF($J35="","",INDEX($AE$34:$AE$220,MATCH($J35,$AF$34:$AF$220,0))) | J35: =IFERROR(LARGE($AF$34:$AF$220,2),"") | M35: =IFERROR(INDEX(GERAL[PONTO],22),"") | N35: =IF(M35="","",IFERROR(INDEX(GERAL[ACUMULADA],22),0)) | O35: =IF(N35="","",$B$11-N35) | P35: =IF(N35="","",IF(N35*1.15<=30,30,IF(N35*1.15<=45,45,IF(N35*1.15<=75,75,IF(N35*1.15<=112.5,112.5,IF(N35*1.15<=150,150,IF(N35*1.15<=225,225,300))))))) | Q35: =IF(P35="","",IFERROR(N35/P35,0)) | R35: =IF(M35="","",IFERROR(INDEX(Tabela7[QT %],MATCH(M35,Tabela7[PONTO],0)),0)) | S35: =IF(N35="","",IFERROR(1-ABS(N35-O35)/$B$11,0)) | T35: =IF(M35="","",IF($B$9>$B$8,IFERROR((INDEX(GERAL[SNAP],22)-$B$8)/($B$9-$B$8),0),0)) | U35: =IF(OR(M35="",V35<>"ESQUERDO"),"",$L$2*IFERROR(N35/$B$11,0)+$L$3*IF($D$11>0,IFERROR(R35/$D$11,0),0)+$L$4*IFERROR(S35,0)-$L$5*IFERROR(T35,0)-$L$6*MAX(0,IFERROR(Q35,0)-$L$7)+ROW()/1000000) | V35: =IFERROR(INDEX(GERAL[LADO],22),"") | X35: =IFERROR(INDEX(GERAL[PONTO],2),"") | Y35: =IF(X35="","",IFERROR(INDEX(GERAL[ACUMULADA],2),0)) | Z35: =IF(Y35="","",$B$31-Y35) | AA35: =IF(Y35="","",IF(Y35*1.15<=30,30,IF(Y35*1.15<=45,45,IF(Y35*1.15<=75,75,IF(Y35*1.15<=112.5,112.5,IF(Y35*1.15<=150,150,IF(Y35*1.15<=225,225,300))))))) | AB35: =IF(AA35="","",IFERROR(Y35/AA35,0)) | AC35: =IF(X35="","",IFERROR(INDEX(DIR_ATUAL[QT %],MATCH(X35,DIR_ATUAL[PONTO],0)),0)) | AD35: =IF(Y35="","",IFERROR(1-ABS(Y35-Z35)/$B$31,0)) | AE35: =IF(X35="","",IF($E$9>$E$8,IFERROR((INDEX(GERAL[SNAP],2)-$E$8)/($E$9-$E$8),0),0)) | AF35: =IF(OR(X35="",AG35<>"DIREITO"),"",$L$2*IFERROR(Y35/$B$31,0)+$L$3*IF($D$31>0,IFERROR(AC35/$D$31,0),0)+$L$4*IFERROR(AD35,0)-$L$5*IFERROR(AE35,0)-$L$6*MAX(0,IFERROR(AB35,0)-$L$7)+ROW()/1000000) | AG35: =IFERROR(INDEX(GERAL[LADO],2),"")
A36: 3 | B36: =IF($J36="","",INDEX($X$34:$X$220,MATCH($J36,$AF$34:$AF$220,0))) | C36: =IF($J36="","",INDEX($Y$34:$Y$220,MATCH($J36,$AF$34:$AF$220,0))) | D36: =IF($J36="","",INDEX($Z$34:$Z$220,MATCH($J36,$AF$34:$AF$220,0))) | E36: =IF($J36="","",INDEX($AA$34:$AA$220,MATCH($J36,$AF$34:$AF$220,0))) | F36: =IF($J36="","",INDEX($AB$34:$AB$220,MATCH($J36,$AF$34:$AF$220,0))) | G36: =IF($J36="","",INDEX($AC$34:$AC$220,MATCH($J36,$AF$34:$AF$220,0))) | H36: =IF($J36="","",INDEX($AD$34:$AD$220,MATCH($J36,$AF$34:$AF$220,0))) | I36: =IF($J36="","",INDEX($AE$34:$AE$220,MATCH($J36,$AF$34:$AF$220,0))) | J36: =IFERROR(LARGE($AF$34:$AF$220,3),"") | M36: =IFERROR(INDEX(GERAL[PONTO],23),"") | N36: =IF(M36="","",IFERROR(INDEX(GERAL[ACUMULADA],23),0)) | O36: =IF(N36="","",$B$11-N36) | P36: =IF(N36="","",IF(N36*1.15<=30,30,IF(N36*1.15<=45,45,IF(N36*1.15<=75,75,IF(N36*1.15<=112.5,112.5,IF(N36*1.15<=150,150,IF(N36*1.15<=225,225,300))))))) | Q36: =IF(P36="","",IFERROR(N36/P36,0)) | R36: =IF(M36="","",IFERROR(INDEX(Tabela7[QT %],MATCH(M36,Tabela7[PONTO],0)),0)) | S36: =IF(N36="","",IFERROR(1-ABS(N36-O36)/$B$11,0)) | T36: =IF(M36="","",IF($B$9>$B$8,IFERROR((INDEX(GERAL[SNAP],23)-$B$8)/($B$9-$B$8),0),0)) | U36: =IF(OR(M36="",V36<>"ESQUERDO"),"",$L$2*IFERROR(N36/$B$11,0)+$L$3*IF($D$11>0,IFERROR(R36/$D$11,0),0)+$L$4*IFERROR(S36,0)-$L$5*IFERROR(T36,0)-$L$6*MAX(0,IFERROR(Q36,0)-$L$7)+ROW()/1000000) | V36: =IFERROR(INDEX(GERAL[LADO],23),"") | X36: =IFERROR(INDEX(GERAL[PONTO],3),"") | Y36: =IF(X36="","",IFERROR(INDEX(GERAL[ACUMULADA],3),0)) | Z36: =IF(Y36="","",$B$31-Y36) | AA36: =IF(Y36="","",IF(Y36*1.15<=30,30,IF(Y36*1.15<=45,45,IF(Y36*1.15<=75,75,IF(Y36*1.15<=112.5,112.5,IF(Y36*1.15<=150,150,IF(Y36*1.15<=225,225,300))))))) | AB36: =IF(AA36="","",IFERROR(Y36/AA36,0)) | AC36: =IF(X36="","",IFERROR(INDEX(DIR_ATUAL[QT %],MATCH(X36,DIR_ATUAL[PONTO],0)),0)) | AD36: =IF(Y36="","",IFERROR(1-ABS(Y36-Z36)/$B$31,0)) | AE36: =IF(X36="","",IF($E$9>$E$8,IFERROR((INDEX(GERAL[SNAP],3)-$E$8)/($E$9-$E$8),0),0)) | AF36: =IF(OR(X36="",AG36<>"DIREITO"),"",$L$2*IFERROR(Y36/$B$31,0)+$L$3*IF($D$31>0,IFERROR(AC36/$D$31,0),0)+$L$4*IFERROR(AD36,0)-$L$5*IFERROR(AE36,0)-$L$6*MAX(0,IFERROR(AB36,0)-$L$7)+ROW()/1000000) | AG36: =IFERROR(INDEX(GERAL[LADO],3),"")
A37: 4 | B37: =IF($J37="","",INDEX($X$34:$X$220,MATCH($J37,$AF$34:$AF$220,0))) | C37: =IF($J37="","",INDEX($Y$34:$Y$220,MATCH($J37,$AF$34:$AF$220,0))) | D37: =IF($J37="","",INDEX($Z$34:$Z$220,MATCH($J37,$AF$34:$AF$220,0))) | E37: =IF($J37="","",INDEX($AA$34:$AA$220,MATCH($J37,$AF$34:$AF$220,0))) | F37: =IF($J37="","",INDEX($AB$34:$AB$220,MATCH($J37,$AF$34:$AF$220,0))) | G37: =IF($J37="","",INDEX($AC$34:$AC$220,MATCH($J37,$AF$34:$AF$220,0))) | H37: =IF($J37="","",INDEX($AD$34:$AD$220,MATCH($J37,$AF$34:$AF$220,0))) | I37: =IF($J37="","",INDEX($AE$34:$AE$220,MATCH($J37,$AF$34:$AF$220,0))) | J37: =IFERROR(LARGE($AF$34:$AF$220,4),"") | M37: =IFERROR(INDEX(GERAL[PONTO],24),"") | N37: =IF(M37="","",IFERROR(INDEX(GERAL[ACUMULADA],24),0)) | O37: =IF(N37="","",$B$11-N37) | P37: =IF(N37="","",IF(N37*1.15<=30,30,IF(N37*1.15<=45,45,IF(N37*1.15<=75,75,IF(N37*1.15<=112.5,112.5,IF(N37*1.15<=150,150,IF(N37*1.15<=225,225,300))))))) | Q37: =IF(P37="","",IFERROR(N37/P37,0)) | R37: =IF(M37="","",IFERROR(INDEX(Tabela7[QT %],MATCH(M37,Tabela7[PONTO],0)),0)) | S37: =IF(N37="","",IFERROR(1-ABS(N37-O37)/$B$11,0)) | T37: =IF(M37="","",IF($B$9>$B$8,IFERROR((INDEX(GERAL[SNAP],24)-$B$8)/($B$9-$B$8),0),0)) | U37: =IF(OR(M37="",V37<>"ESQUERDO"),"",$L$2*IFERROR(N37/$B$11,0)+$L$3*IF($D$11>0,IFERROR(R37/$D$11,0),0)+$L$4*IFERROR(S37,0)-$L$5*IFERROR(T37,0)-$L$6*MAX(0,IFERROR(Q37,0)-$L$7)+ROW()/1000000) | V37: =IFERROR(INDEX(GERAL[LADO],24),"") | X37: =IFERROR(INDEX(GERAL[PONTO],4),"") | Y37: =IF(X37="","",IFERROR(INDEX(GERAL[ACUMULADA],4),0)) | Z37: =IF(Y37="","",$B$31-Y37) | AA37: =IF(Y37="","",IF(Y37*1.15<=30,30,IF(Y37*1.15<=45,45,IF(Y37*1.15<=75,75,IF(Y37*1.15<=112.5,112.5,IF(Y37*1.15<=150,150,IF(Y37*1.15<=225,225,300))))))) | AB37: =IF(AA37="","",IFERROR(Y37/AA37,0)) | AC37: =IF(X37="","",IFERROR(INDEX(DIR_ATUAL[QT %],MATCH(X37,DIR_ATUAL[PONTO],0)),0)) | AD37: =IF(Y37="","",IFERROR(1-ABS(Y37-Z37)/$B$31,0)) | AE37: =IF(X37="","",IF($E$9>$E$8,IFERROR((INDEX(GERAL[SNAP],4)-$E$8)/($E$9-$E$8),0),0)) | AF37: =IF(OR(X37="",AG37<>"DIREITO"),"",$L$2*IFERROR(Y37/$B$31,0)+$L$3*IF($D$31>0,IFERROR(AC37/$D$31,0),0)+$L$4*IFERROR(AD37,0)-$L$5*IFERROR(AE37,0)-$L$6*MAX(0,IFERROR(AB37,0)-$L$7)+ROW()/1000000) | AG37: =IFERROR(INDEX(GERAL[LADO],4),"")
A38: 5 | B38: =IF($J38="","",INDEX($X$34:$X$220,MATCH($J38,$AF$34:$AF$220,0))) | C38: =IF($J38="","",INDEX($Y$34:$Y$220,MATCH($J38,$AF$34:$AF$220,0))) | D38: =IF($J38="","",INDEX($Z$34:$Z$220,MATCH($J38,$AF$34:$AF$220,0))) | E38: =IF($J38="","",INDEX($AA$34:$AA$220,MATCH($J38,$AF$34:$AF$220,0))) | F38: =IF($J38="","",INDEX($AB$34:$AB$220,MATCH($J38,$AF$34:$AF$220,0))) | G38: =IF($J38="","",INDEX($AC$34:$AC$220,MATCH($J38,$AF$34:$AF$220,0))) | H38: =IF($J38="","",INDEX($AD$34:$AD$220,MATCH($J38,$AF$34:$AF$220,0))) | I38: =IF($J38="","",INDEX($AE$34:$AE$220,MATCH($J38,$AF$34:$AF$220,0))) | J38: =IFERROR(LARGE($AF$34:$AF$220,5),"") | M38: =IFERROR(INDEX(GERAL[PONTO],25),"") | N38: =IF(M38="","",IFERROR(INDEX(GERAL[ACUMULADA],25),0)) | O38: =IF(N38="","",$B$11-N38) | P38: =IF(N38="","",IF(N38*1.15<=30,30,IF(N38*1.15<=45,45,IF(N38*1.15<=75,75,IF(N38*1.15<=112.5,112.5,IF(N38*1.15<=150,150,IF(N38*1.15<=225,225,300))))))) | Q38: =IF(P38="","",IFERROR(N38/P38,0)) | R38: =IF(M38="","",IFERROR(INDEX(Tabela7[QT %],MATCH(M38,Tabela7[PONTO],0)),0)) | S38: =IF(N38="","",IFERROR(1-ABS(N38-O38)/$B$11,0)) | T38: =IF(M38="","",IF($B$9>$B$8,IFERROR((INDEX(GERAL[SNAP],25)-$B$8)/($B$9-$B$8),0),0)) | U38: =IF(OR(M38="",V38<>"ESQUERDO"),"",$L$2*IFERROR(N38/$B$11,0)+$L$3*IF($D$11>0,IFERROR(R38/$D$11,0),0)+$L$4*IFERROR(S38,0)-$L$5*IFERROR(T38,0)-$L$6*MAX(0,IFERROR(Q38,0)-$L$7)+ROW()/1000000) | V38: =IFERROR(INDEX(GERAL[LADO],25),"") | X38: =IFERROR(INDEX(GERAL[PONTO],5),"") | Y38: =IF(X38="","",IFERROR(INDEX(GERAL[ACUMULADA],5),0)) | Z38: =IF(Y38="","",$B$31-Y38) | AA38: =IF(Y38="","",IF(Y38*1.15<=30,30,IF(Y38*1.15<=45,45,IF(Y38*1.15<=75,75,IF(Y38*1.15<=112.5,112.5,IF(Y38*1.15<=150,150,IF(Y38*1.15<=225,225,300))))))) | AB38: =IF(AA38="","",IFERROR(Y38/AA38,0)) | AC38: =IF(X38="","",IFERROR(INDEX(DIR_ATUAL[QT %],MATCH(X38,DIR_ATUAL[PONTO],0)),0)) | AD38: =IF(Y38="","",IFERROR(1-ABS(Y38-Z38)/$B$31,0)) | AE38: =IF(X38="","",IF($E$9>$E$8,IFERROR((INDEX(GERAL[SNAP],5)-$E$8)/($E$9-$E$8),0),0)) | AF38: =IF(OR(X38="",AG38<>"DIREITO"),"",$L$2*IFERROR(Y38/$B$31,0)+$L$3*IF($D$31>0,IFERROR(AC38/$D$31,0),0)+$L$4*IFERROR(AD38,0)-$L$5*IFERROR(AE38,0)-$L$6*MAX(0,IFERROR(AB38,0)-$L$7)+ROW()/1000000) | AG38: =IFERROR(INDEX(GERAL[LADO],5),"")
A39: 6 | B39: =IF($J39="","",INDEX($X$34:$X$220,MATCH($J39,$AF$34:$AF$220,0))) | C39: =IF($J39="","",INDEX($Y$34:$Y$220,MATCH($J39,$AF$34:$AF$220,0))) | D39: =IF($J39="","",INDEX($Z$34:$Z$220,MATCH($J39,$AF$34:$AF$220,0))) | E39: =IF($J39="","",INDEX($AA$34:$AA$220,MATCH($J39,$AF$34:$AF$220,0))) | F39: =IF($J39="","",INDEX($AB$34:$AB$220,MATCH($J39,$AF$34:$AF$220,0))) | G39: =IF($J39="","",INDEX($AC$34:$AC$220,MATCH($J39,$AF$34:$AF$220,0))) | H39: =IF($J39="","",INDEX($AD$34:$AD$220,MATCH($J39,$AF$34:$AF$220,0))) | I39: =IF($J39="","",INDEX($AE$34:$AE$220,MATCH($J39,$AF$34:$AF$220,0))) | J39: =IFERROR(LARGE($AF$34:$AF$220,6),"") | M39: =IFERROR(INDEX(GERAL[PONTO],26),"") | N39: =IF(M39="","",IFERROR(INDEX(GERAL[ACUMULADA],26),0)) | O39: =IF(N39="","",$B$11-N39) | P39: =IF(N39="","",IF(N39*1.15<=30,30,IF(N39*1.15<=45,45,IF(N39*1.15<=75,75,IF(N39*1.15<=112.5,112.5,IF(N39*1.15<=150,150,IF(N39*1.15<=225,225,300))))))) | Q39: =IF(P39="","",IFERROR(N39/P39,0)) | R39: =IF(M39="","",IFERROR(INDEX(Tabela7[QT %],MATCH(M39,Tabela7[PONTO],0)),0)) | S39: =IF(N39="","",IFERROR(1-ABS(N39-O39)/$B$11,0)) | T39: =IF(M39="","",IF($B$9>$B$8,IFERROR((INDEX(GERAL[SNAP],26)-$B$8)/($B$9-$B$8),0),0)) | U39: =IF(OR(M39="",V39<>"ESQUERDO"),"",$L$2*IFERROR(N39/$B$11,0)+$L$3*IF($D$11>0,IFERROR(R39/$D$11,0),0)+$L$4*IFERROR(S39,0)-$L$5*IFERROR(T39,0)-$L$6*MAX(0,IFERROR(Q39,0)-$L$7)+ROW()/1000000) | V39: =IFERROR(INDEX(GERAL[LADO],26),"") | X39: =IFERROR(INDEX(GERAL[PONTO],6),"") | Y39: =IF(X39="","",IFERROR(INDEX(GERAL[ACUMULADA],6),0)) | Z39: =IF(Y39="","",$B$31-Y39) | AA39: =IF(Y39="","",IF(Y39*1.15<=30,30,IF(Y39*1.15<=45,45,IF(Y39*1.15<=75,75,IF(Y39*1.15<=112.5,112.5,IF(Y39*1.15<=150,150,IF(Y39*1.15<=225,225,300))))))) | AB39: =IF(AA39="","",IFERROR(Y39/AA39,0)) | AC39: =IF(X39="","",IFERROR(INDEX(DIR_ATUAL[QT %],MATCH(X39,DIR_ATUAL[PONTO],0)),0)) | AD39: =IF(Y39="","",IFERROR(1-ABS(Y39-Z39)/$B$31,0)) | AE39: =IF(X39="","",IF($E$9>$E$8,IFERROR((INDEX(GERAL[SNAP],6)-$E$8)/($E$9-$E$8),0),0)) | AF39: =IF(OR(X39="",AG39<>"DIREITO"),"",$L$2*IFERROR(Y39/$B$31,0)+$L$3*IF($D$31>0,IFERROR(AC39/$D$31,0),0)+$L$4*IFERROR(AD39,0)-$L$5*IFERROR(AE39,0)-$L$6*MAX(0,IFERROR(AB39,0)-$L$7)+ROW()/1000000) | AG39: =IFERROR(INDEX(GERAL[LADO],6),"")
A40: 7 | B40: =IF($J40="","",INDEX($X$34:$X$220,MATCH($J40,$AF$34:$AF$220,0))) | C40: =IF($J40="","",INDEX($Y$34:$Y$220,MATCH($J40,$AF$34:$AF$220,0))) | D40: =IF($J40="","",INDEX($Z$34:$Z$220,MATCH($J40,$AF$34:$AF$220,0))) | E40: =IF($J40="","",INDEX($AA$34:$AA$220,MATCH($J40,$AF$34:$AF$220,0))) | F40: =IF($J40="","",INDEX($AB$34:$AB$220,MATCH($J40,$AF$34:$AF$220,0))) | G40: =IF($J40="","",INDEX($AC$34:$AC$220,MATCH($J40,$AF$34:$AF$220,0))) | H40: =IF($J40="","",INDEX($AD$34:$AD$220,MATCH($J40,$AF$34:$AF$220,0))) | I40: =IF($J40="","",INDEX($AE$34:$AE$220,MATCH($J40,$AF$34:$AF$220,0))) | J40: =IFERROR(LARGE($AF$34:$AF$220,7),"") | M40: =IFERROR(INDEX(GERAL[PONTO],27),"") | N40: =IF(M40="","",IFERROR(INDEX(GERAL[ACUMULADA],27),0)) | O40: =IF(N40="","",$B$11-N40) | P40: =IF(N40="","",IF(N40*1.15<=30,30,IF(N40*1.15<=45,45,IF(N40*1.15<=75,75,IF(N40*1.15<=112.5,112.5,IF(N40*1.15<=150,150,IF(N40*1.15<=225,225,300))))))) | Q40: =IF(P40="","",IFERROR(N40/P40,0)) | R40: =IF(M40="","",IFERROR(INDEX(Tabela7[QT %],MATCH(M40,Tabela7[PONTO],0)),0)) | S40: =IF(N40="","",IFERROR(1-ABS(N40-O40)/$B$11,0)) | T40: =IF(M40="","",IF($B$9>$B$8,IFERROR((INDEX(GERAL[SNAP],27)-$B$8)/($B$9-$B$8),0),0)) | U40: =IF(OR(M40="",V40<>"ESQUERDO"),"",$L$2*IFERROR(N40/$B$11,0)+$L$3*IF($D$11>0,IFERROR(R40/$D$11,0),0)+$L$4*IFERROR(S40,0)-$L$5*IFERROR(T40,0)-$L$6*MAX(0,IFERROR(Q40,0)-$L$7)+ROW()/1000000) | V40: =IFERROR(INDEX(GERAL[LADO],27),"") | X40: =IFERROR(INDEX(GERAL[PONTO],7),"") | Y40: =IF(X40="","",IFERROR(INDEX(GERAL[ACUMULADA],7),0)) | Z40: =IF(Y40="","",$B$31-Y40) | AA40: =IF(Y40="","",IF(Y40*1.15<=30,30,IF(Y40*1.15<=45,45,IF(Y40*1.15<=75,75,IF(Y40*1.15<=112.5,112.5,IF(Y40*1.15<=150,150,IF(Y40*1.15<=225,225,300))))))) | AB40: =IF(AA40="","",IFERROR(Y40/AA40,0)) | AC40: =IF(X40="","",IFERROR(INDEX(DIR_ATUAL[QT %],MATCH(X40,DIR_ATUAL[PONTO],0)),0)) | AD40: =IF(Y40="","",IFERROR(1-ABS(Y40-Z40)/$B$31,0)) | AE40: =IF(X40="","",IF($E$9>$E$8,IFERROR((INDEX(GERAL[SNAP],7)-$E$8)/($E$9-$E$8),0),0)) | AF40: =IF(OR(X40="",AG40<>"DIREITO"),"",$L$2*IFERROR(Y40/$B$31,0)+$L$3*IF($D$31>0,IFERROR(AC40/$D$31,0),0)+$L$4*IFERROR(AD40,0)-$L$5*IFERROR(AE40,0)-$L$6*MAX(0,IFERROR(AB40,0)-$L$7)+ROW()/1000000) | AG40: =IFERROR(INDEX(GERAL[LADO],7),"")
A41: 8 | B41: =IF($J41="","",INDEX($X$34:$X$220,MATCH($J41,$AF$34:$AF$220,0))) | C41: =IF($J41="","",INDEX($Y$34:$Y$220,MATCH($J41,$AF$34:$AF$220,0))) | D41: =IF($J41="","",INDEX($Z$34:$Z$220,MATCH($J41,$AF$34:$AF$220,0))) | E41: =IF($J41="","",INDEX($AA$34:$AA$220,MATCH($J41,$AF$34:$AF$220,0))) | F41: =IF($J41="","",INDEX($AB$34:$AB$220,MATCH($J41,$AF$34:$AF$220,0))) | G41: =IF($J41="","",INDEX($AC$34:$AC$220,MATCH($J41,$AF$34:$AF$220,0))) | H41: =IF($J41="","",INDEX($AD$34:$AD$220,MATCH($J41,$AF$34:$AF$220,0))) | I41: =IF($J41="","",INDEX($AE$34:$AE$220,MATCH($J41,$AF$34:$AF$220,0))) | J41: =IFERROR(LARGE($AF$34:$AF$220,8),"") | M41: =IFERROR(INDEX(GERAL[PONTO],28),"") | N41: =IF(M41="","",IFERROR(INDEX(GERAL[ACUMULADA],28),0)) | O41: =IF(N41="","",$B$11-N41) | P41: =IF(N41="","",IF(N41*1.15<=30,30,IF(N41*1.15<=45,45,IF(N41*1.15<=75,75,IF(N41*1.15<=112.5,112.5,IF(N41*1.15<=150,150,IF(N41*1.15<=225,225,300))))))) | Q41: =IF(P41="","",IFERROR(N41/P41,0)) | R41: =IF(M41="","",IFERROR(INDEX(Tabela7[QT %],MATCH(M41,Tabela7[PONTO],0)),0)) | S41: =IF(N41="","",IFERROR(1-ABS(N41-O41)/$B$11,0)) | T41: =IF(M41="","",IF($B$9>$B$8,IFERROR((INDEX(GERAL[SNAP],28)-$B$8)/($B$9-$B$8),0),0)) | U41: =IF(OR(M41="",V41<>"ESQUERDO"),"",$L$2*IFERROR(N41/$B$11,0)+$L$3*IF($D$11>0,IFERROR(R41/$D$11,0),0)+$L$4*IFERROR(S41,0)-$L$5*IFERROR(T41,0)-$L$6*MAX(0,IFERROR(Q41,0)-$L$7)+ROW()/1000000) | V41: =IFERROR(INDEX(GERAL[LADO],28),"") | X41: =IFERROR(INDEX(GERAL[PONTO],8),"") | Y41: =IF(X41="","",IFERROR(INDEX(GERAL[ACUMULADA],8),0)) | Z41: =IF(Y41="","",$B$31-Y41) | AA41: =IF(Y41="","",IF(Y41*1.15<=30,30,IF(Y41*1.15<=45,45,IF(Y41*1.15<=75,75,IF(Y41*1.15<=112.5,112.5,IF(Y41*1.15<=150,150,IF(Y41*1.15<=225,225,300))))))) | AB41: =IF(AA41="","",IFERROR(Y41/AA41,0)) | AC41: =IF(X41="","",IFERROR(INDEX(DIR_ATUAL[QT %],MATCH(X41,DIR_ATUAL[PONTO],0)),0)) | AD41: =IF(Y41="","",IFERROR(1-ABS(Y41-Z41)/$B$31,0)) | AE41: =IF(X41="","",IF($E$9>$E$8,IFERROR((INDEX(GERAL[SNAP],8)-$E$8)/($E$9-$E$8),0),0)) | AF41: =IF(OR(X41="",AG41<>"DIREITO"),"",$L$2*IFERROR(Y41/$B$31,0)+$L$3*IF($D$31>0,IFERROR(AC41/$D$31,0),0)+$L$4*IFERROR(AD41,0)-$L$5*IFERROR(AE41,0)-$L$6*MAX(0,IFERROR(AB41,0)-$L$7)+ROW()/1000000) | AG41: =IFERROR(INDEX(GERAL[LADO],8),"")
...

Sheet RAMAL
A1: Ampacidade dos Condutores de Ramais de BT (A)
A2: Item | B2: Condutores Fora de Padrão | M2: Condutores Padrão
